Workbook

Sheet Results Summary
A1: =Codeine!A4 -> Method/SOP | D1: =Codeine!D4 -> Column Lot #: | H1: =Codeine!H4 -> Urine Lot #: | M1: =Codeine!J4 -> Standards Date:
A2: =Codeine!A5 -> Batch ID: | D2: =Codeine!D5 -> Instrument: | H2: =Codeine!H5 -> Analyst: | M2: =Codeine!J5 -> Reviewer:
A3: Name | B3: Data File | C3: Acq. Date-Time | D3: Codeine | E3: Amphetamine | F3: Norfentanyl | G3: Norcarfentanil | H3: Xylazine | I3: Heroin | J3: Cocaine | K3: Acetyl Fentanyl | L3: Acryl Fentanyl | M3: Fentanyl | N3: 4-ANPP | O3: para-Fluorofentanyl | P3: Carfentanil | Q3: Lorazepam
A4: =Norfentanyl!A38 -> 0 | B4: =Norfentanyl!B38 -> 0 | C4: =Norfentanyl!C38 -> 0 | D4: =Codeine!O38 -> #DIV/0! | E4: =Amphetamine!O38 -> #DIV/0! | F4: =Norfentanyl!O38 -> #DIV/0! | G4: =Norcarfentanil!O38 -> #DIV/0! | H4: =Xylazine!O38 -> #DIV/0! | I4: =Heroin!O38 -> #DIV/0! | J4: =Cocaine!O38 -> #DIV/0! | K4: ='Acetyl Fentanyl'!O38 -> #DIV/0! | L4: ='Acryl Fentanyl'!O38 -> #DIV/0! | M4: =Fentanyl!O38 -> #DIV/0! | N4: ='4-ANPP'!O38 -> #DIV/0! | O4: ='para-Fluorofentanyl'!O38 -> #DIV/0! | P4: =Carfentanil!O38 -> #DIV/0! | Q4: =Lorazepam!O38 -> #DIV/0!
A5: =Norfentanyl!A39 -> 0 | B5: =Norfentanyl!B39 -> 0 | C5: =Norfentanyl!C39 -> 0 | D5: =Codeine!O39 -> #DIV/0! | E5: =Amphetamine!O39 -> #DIV/0! | F5: =Norfentanyl!O39 -> #DIV/0! | G5: =Norcarfentanil!O39 -> #DIV/0! | H5: =Xylazine!O39 -> #DIV/0! | I5: =Heroin!O39 -> #DIV/0! | J5: =Cocaine!O39 -> #DIV/0! | K5: ='Acetyl Fentanyl'!O39 -> #DIV/0! | L5: ='Acryl Fentanyl'!O39 -> #DIV/0! | M5: =Fentanyl!O39 -> #DIV/0! | N5: ='4-ANPP'!O39 -> #DIV/0! | O5: ='para-Fluorofentanyl'!O39 -> #DIV/0! | P5: =Carfentanil!O39 -> #DIV/0! | Q5: =Lorazepam!O39 -> #DIV/0!
A6: =Norfentanyl!A40 -> 0 | B6: =Norfentanyl!B40 -> 0 | C6: =Norfentanyl!C40 -> 0 | D6: =Codeine!O40 -> #DIV/0! | E6: =Amphetamine!O40 -> #DIV/0! | F6: =Norfentanyl!O40 -> #DIV/0! | G6: =Norcarfentanil!O40 -> #DIV/0! | H6: =Xylazine!O40 -> #DIV/0! | I6: =Heroin!O40 -> #DIV/0! | J6: =Cocaine!O40 -> #DIV/0! | K6: ='Acetyl Fentanyl'!O40 -> #DIV/0! | L6: ='Acryl Fentanyl'!O40 -> #DIV/0! | M6: =Fentanyl!O40 -> #DIV/0! | N6: ='4-ANPP'!O40 -> #DIV/0! | O6: ='para-Fluorofentanyl'!O40 -> #DIV/0! | P6: =Carfentanil!O40 -> #DIV/0! | Q6: =Lorazepam!O40 -> #DIV/0!
A7: =Norfentanyl!A41 -> 0 | B7: =Norfentanyl!B41 -> 0 | C7: =Norfentanyl!C41 -> 0 | D7: =Codeine!O41 -> #DIV/0! | E7: =Amphetamine!O41 -> #DIV/0! | F7: =Norfentanyl!O41 -> #DIV/0! | G7: =Norcarfentanil!O41 -> #DIV/0! | H7: =Xylazine!O41 -> #DIV/0! | I7: =Heroin!O41 -> #DIV/0! | J7: =Cocaine!O41 -> #DIV/0! | K7: ='Acetyl Fentanyl'!O41 -> #DIV/0! | L7: ='Acryl Fentanyl'!O41 -> #DIV/0! | M7: =Fentanyl!O41 -> #DIV/0! | N7: ='4-ANPP'!O41 -> #DIV/0! | O7: ='para-Fluorofentanyl'!O41 -> #DIV/0! | P7: =Carfentanil!O41 -> #DIV/0! | Q7: =Lorazepam!O41 -> #DIV/0!
A8: =Norfentanyl!A42 -> 0 | B8: =Norfentanyl!B42 -> 0 | C8: =Norfentanyl!C42 -> 0 | D8: =Codeine!O42 -> #DIV/0! | E8: =Amphetamine!O42 -> #DIV/0! | F8: =Norfentanyl!O42 -> #DIV/0! | G8: =Norcarfentanil!O42 -> #DIV/0! | H8: =Xylazine!O42 -> #DIV/0! | I8: =Heroin!O42 -> #DIV/0! | J8: =Cocaine!O42 -> #DIV/0! | K8: ='Acetyl Fentanyl'!O42 -> #DIV/0! | L8: ='Acryl Fentanyl'!O42 -> #DIV/0! | M8: =Fentanyl!O42 -> #DIV/0! | N8: ='4-ANPP'!O42 -> #DIV/0! | O8: ='para-Fluorofentanyl'!O42 -> #DIV/0! | P8: =Carfentanil!O42 -> #DIV/0! | Q8: =Lorazepam!O42 -> #DIV/0!
A9: =Norfentanyl!A43 -> 0 | B9: =Norfentanyl!B43 -> 0 | C9: =Norfentanyl!C43 -> 0 | D9: =Codeine!O43 -> #DIV/0! | E9: =Amphetamine!O43 -> #DIV/0! | F9: =Norfentanyl!O43 -> #DIV/0! | G9: =Norcarfentanil!O43 -> #DIV/0! | H9: =Xylazine!O43 -> #DIV/0! | I9: =Heroin!O43 -> #DIV/0! | J9: =Cocaine!O43 -> #DIV/0! | K9: ='Acetyl Fentanyl'!O43 -> #DIV/0! | L9: ='Acryl Fentanyl'!O43 -> #DIV/0! | M9: =Fentanyl!O43 -> #DIV/0! | N9: ='4-ANPP'!O43 -> #DIV/0! | O9: ='para-Fluorofentanyl'!O43 -> #DIV/0! | P9: =Carfentanil!O43 -> #DIV/0! | Q9: =Lorazepam!O43 -> #DIV/0!
A10: =Norfentanyl!A44 -> 0 | B10: =Norfentanyl!B44 -> 0 | C10: =Norfentanyl!C44 -> 0 | D10: =Codeine!O44 -> #DIV/0! | E10: =Amphetamine!O44 -> #DIV/0! | F10: =Norfentanyl!O44 -> #DIV/0! | G10: =Norcarfentanil!O44 -> #DIV/0! | H10: =Xylazine!O44 -> #DIV/0! | I10: =Heroin!O44 -> #DIV/0! | J10: =Cocaine!O44 -> #DIV/0! | K10: ='Acetyl Fentanyl'!O44 -> #DIV/0! | L10: ='Acryl Fentanyl'!O44 -> #DIV/0! | M10: =Fentanyl!O44 -> #DIV/0! | N10: ='4-ANPP'!O44 -> #DIV/0! | O10: ='para-Fluorofentanyl'!O44 -> #DIV/0! | P10: =Carfentanil!O44 -> #DIV/0! | Q10: =Lorazepam!O44 -> #DIV/0!
A11: =Norfentanyl!A45 -> 0 | B11: =Norfentanyl!B45 -> 0 | C11: =Norfentanyl!C45 -> 0 | D11: =Codeine!O45 -> #DIV/0! | E11: =Amphetamine!O45 -> #DIV/0! | F11: =Norfentanyl!O45 -> #DIV/0! | G11: =Norcarfentanil!O45 -> #DIV/0! | H11: =Xylazine!O45 -> #DIV/0! | I11: =Heroin!O45 -> #DIV/0! | J11: =Cocaine!O45 -> #DIV/0! | K11: ='Acetyl Fentanyl'!O45 -> #DIV/0! | L11: ='Acryl Fentanyl'!O45 -> #DIV/0! | M11: =Fentanyl!O45 -> #DIV/0! | N11: ='4-ANPP'!O45 -> #DIV/0! | O11: ='para-Fluorofentanyl'!O45 -> #DIV/0! | P11: =Carfentanil!O45 -> #DIV/0! | Q11: =Lorazepam!O45 -> #DIV/0!
A12: =Norfentanyl!A46 -> 0 | B12: =Norfentanyl!B46 -> 0 | C12: =Norfentanyl!C46 -> 0 | D12: =Codeine!O46 -> #DIV/0! | E12: =Amphetamine!O46 -> #DIV/0! | F12: =Norfentanyl!O46 -> #DIV/0! | G12: =Norcarfentanil!O46 -> #DIV/0! | H12: =Xylazine!O46 -> #DIV/0! | I12: =Heroin!O46 -> #DIV/0! | J12: =Cocaine!O46 -> #DIV/0! | K12: ='Acetyl Fentanyl'!O46 -> #DIV/0! | L12: ='Acryl Fentanyl'!O46 -> #DIV/0! | M12: =Fentanyl!O46 -> #DIV/0! | N12: ='4-ANPP'!O46 -> #DIV/0! | O12: ='para-Fluorofentanyl'!O46 -> #DIV/0! | P12: =Carfentanil!O46 -> #DIV/0! | Q12: =Lorazepam!O46 -> #DIV/0!
A13: =Norfentanyl!A47 -> 0 | B13: =Norfentanyl!B47 -> 0 | C13: =Norfentanyl!C47 -> 0 | D13: =Codeine!O47 -> #DIV/0! | E13: =Amphetamine!O47 -> #DIV/0! | F13: =Norfentanyl!O47 -> #DIV/0! | G13: =Norcarfentanil!O47 -> #DIV/0! | H13: =Xylazine!O47 -> #DIV/0! | I13: =Heroin!O47 -> #DIV/0! | J13: =Cocaine!O47 -> #DIV/0! | K13: ='Acetyl Fentanyl'!O47 -> #DIV/0! | L13: ='Acryl Fentanyl'!O47 -> #DIV/0! | M13: =Fentanyl!O47 -> #DIV/0! | N13: ='4-ANPP'!O47 -> #DIV/0! | O13: ='para-Fluorofentanyl'!O47 -> #DIV/0! | P13: =Carfentanil!O47 -> #DIV/0! | Q13: =Lorazepam!O47 -> #DIV/0!
A14: =Norfentanyl!A48 -> 0 | B14: =Norfentanyl!B48 -> 0 | C14: =Norfentanyl!C48 -> 0 | D14: =Codeine!O48 -> #DIV/0! | E14: =Amphetamine!O48 -> #DIV/0! | F14: =Norfentanyl!O48 -> #DIV/0! | G14: =Norcarfentanil!O48 -> #DIV/0! | H14: =Xylazine!O48 -> #DIV/0! | I14: =Heroin!O48 -> #DIV/0! | J14: =Cocaine!O48 -> #DIV/0! | K14: ='Acetyl Fentanyl'!O48 -> #DIV/0! | L14: ='Acryl Fentanyl'!O48 -> #DIV/0! | M14: =Fentanyl!O48 -> #DIV/0! | N14: ='4-ANPP'!O48 -> #DIV/0! | O14: ='para-Fluorofentanyl'!O48 -> #DIV/0! | P14: =Carfentanil!O48 -> #DIV/0! | Q14: =Lorazepam!O48 -> #DIV/0!
A15: =Norfentanyl!A49 -> 0 | B15: =Norfentanyl!B49 -> 0 | C15: =Norfentanyl!C49 -> 0 | D15: =Codeine!O49 -> #DIV/0! | E15: =Amphetamine!O49 -> #DIV/0! | F15: =Norfentanyl!O49 -> #DIV/0! | G15: =Norcarfentanil!O49 -> #DIV/0! | H15: =Xylazine!O49 -> #DIV/0! | I15: =Heroin!O49 -> #DIV/0! | J15: =Cocaine!O49 -> #DIV/0! | K15: ='Acetyl Fentanyl'!O49 -> #DIV/0! | L15: ='Acryl Fentanyl'!O49 -> #DIV/0! | M15: =Fentanyl!O49 -> #DIV/0! | N15: ='4-ANPP'!O49 -> #DIV/0! | O15: ='para-Fluorofentanyl'!O49 -> #DIV/0! | P15: =Carfentanil!O49 -> #DIV/0! | Q15: =Lorazepam!O49 -> #DIV/0!
... A23: =Norfentanyl!A57 -> 0 | B23: =Norfentanyl!B57 -> 0 | C23: =Norfentanyl!C57 -> 0 | D23: =Codeine!O57 -> #DIV/0! | E23: =Amphetamine!O57 -> #DIV/0! | F23: =Norfentanyl!O57 -> #DIV/0! | G23: =Norcarfentanil!O57 -> #DIV/0! | H23: =Xylazine!O57 -> #DIV/0! | I23: =Heroin!O57 -> #DIV/0! | J23: =Cocaine!O57 -> #DIV/0! | K23: ='Acetyl Fentanyl'!O57 -> #DIV/0! | L23: ='Acryl Fentanyl'!O57 -> #DIV/0! | M23: =Fentanyl!O57 -> #DIV/0! | N23: ='4-ANPP'!O57 -> #DIV/0! | O23: ='para-Fluorofentanyl'!O57 -> #DIV/0! | P23: =Carfentanil!O57 -> #DIV/0! | Q23: =Lorazepam!O57 -> #DIV/0!
A24: Run Comments

Sheet Codeine
A1: Codeine
A4: Method/SOP | D4: Column Lot #: | H4: Urine Lot #: | J4: Standards Date:
A5: Batch ID: | D5: Instrument: | H5: Analyst: | J5: Reviewer:
A7: QC Criteria
A8: Paste LRL and QCH Results in the light blue shaded areas. Paste LRL results in row 17 and QCH results in row 18.
A9: Opening QC
A10: QC Low (LRL) | B10: Response | F10: Retention Time | I10: QC High | J10: Response | N10: Retention Time
B11: 25% of Lowest | D11: Run Value | E11: Pass/Fail | F11: Characterization | H11: Run Value | J11: 25% of Lowest | L11: Run Value | M11: Pass/Fail | N11: Characterization | P11: Run Value
B12: Analytical | C12: 4669.6045 | D12: =E24 -> 0 | E12: =IF(D12>C12,"PASS","FAIL") -> FAIL | F12: Avg | G12: =$D$24 -> 0 | H12: =D24 -> 0 | J12: Analytical | K12: 10662.75 | L12: =E25 -> 0 | M12: =IF(L12>K12,"PASS","FAIL") -> FAIL | N12: Avg | O12: =$D$24 -> 0 | P12: =D25 -> 0
B13: Qualifier | C13: 17.876849 | D13: =J24 -> 0 | E13: =IF(D13>C13,"PASS","FAIL") -> FAIL | F13: 0.1 | G13: =G12+0.1 -> 0.1 | H13: Pass/Fail | J13: Qualifier | K13: 17.925 | L13: =J25 -> 0 | M13: =IF(L13>K13,"PASS","FAIL") -> FAIL | N13: 0.1 | O13: =O12+0.1 -> 0.1 | P13: Pass/Fail
B14: IS | C14: 2402.8789 | D14: =M24 -> 0 | E14: =IF(D14>C14,"PASS","FAIL") -> FAIL | F14: -0.1 | G14: =G12-0.1 -> -0.1 | H14: =IF(AND(H12>G14,H12<G13),"PASS","FAIL") -> PASS | J14: IS | K14: 1948 | L14: =M25 -> 0 | M14: =IF(L14>K14,"PASS","FAIL") -> FAIL | N14: -0.1 | O14: =O12-0.1 -> -0.1 | P14: =IF(AND(P12>O14,P12<O13),"PASS","FAIL") -> PASS
A15: Closing QC
A16: QC Low (LRL) | B16: Response | F16: Retention Time | I16: QC High | J16: Response | N16: Retention Time
B17: 25% of Lowest | D17: Run Value | E17: Pass/Fail | F17: Characterization | H17: Run Value | J17: 25% of Lowest | L17: Run Value | M17: Pass/Fail | N17: Characterization | P17: Run Value
B18: Analytical | C18: 4669.6045 | D18: =E26 -> 0 | E18: =IF(D18>C18,"PASS","FAIL") -> FAIL | F18: Avg | G18: =$D$24 -> 0 | H18: =D26 -> 0 | J18: Analytical | K18: 10662.75 | L18: =E27 -> 0 | M18: =IF(L18>K18,"PASS","FAIL") -> FAIL | N18: Avg | O18: =$D$24 -> 0 | P18: =D27 -> 0
B19: Qualifier | C19: 17.876849 | D19: =J26 -> 0 | E19: =IF(D19>C19,"PASS","FAIL") -> FAIL | F19: 0.1 | G19: =G18+0.1 -> 0.1 | H19: Pass/Fail | J19: Qualifier | K19: 17.925 | L19: =J27 -> 0 | M19: =IF(L19>K19,"PASS","FAIL") -> FAIL | N19: 0.1 | O19: =O18+0.1 -> 0.1 | P19: Pass/Fail
B20: IS | C20: 2402.8789 | D20: =M26 -> 0 | E20: =IF(D20>C20,"PASS","FAIL") -> FAIL | F20: -0.1 | G20: =G18-0.1 -> -0.1 | H20: =IF(AND(H18>G20,H18<G19),"PASS","FAIL") -> PASS | J20: IS | K20: 1948 | L20: =M27 -> 0 | M20: =IF(L20>K20,"PASS","FAIL") -> FAIL | N20: -0.1 | O20: =O18-0.1 -> -0.1 | P20: =IF(AND(P18>O20,P18<O19),"PASS","FAIL") -> PASS
A22: Sample | D22: =D60 -> Codeine Results | I22: =I60 -> Qualifier (300.2 -> 215.1) Method | J22: =J60 -> Qualifier (300.2 -> 215.1) Results | L22: =L60 -> Codeine D3 (ISTD) Results
A23: Name | B23: Data File | C23: Acq. Date-Time | D23: RT | E23: Resp. | F23: MI | G23: S/N | H23: RR | I23: Rel. Resp. | J23: Ratio | K23: MI | L23: RT | M23: Resp. | N23: S/N
A24: Opening QCL
A25: Opening QCH
A26: Closing QCL
A27: Closing QCH
A29: Sample Criteria | Q29: Sample Criteria QC
A30: Paste Sample Results in the light orange shaded areas.If more than 10 samples were analyzed in the bracket, add rows and drag down formulas. Conditional formatting will highlight RED if the sample fails for the criteria and GREEN if it passes for the criteria. All criteria must be GREEN for a sample to be considered a DETECT.
A31: 20 Samples between QCs? | B31: Yes | C31: 1. Retention Time | E31: 2. Analyte Response | H31: 3. Resp. Ratio | I31: 4. Qualifier | M31: 5. ISTD | O31: Sample Result
C32: In-Run QCL RT | D32: =$D$24 -> 0 | E32: In-Run QCL Response Threshold | H32: In-Run QCL RR | J32: Qualifier Ion Ratio Limits | M32: Response Threshold
C33: RT Limits | D33: =D32-0.1 -> -0.1
D34: =(D32+0.1) -> 0.1 | E34: =E24 -> 0 | H34: =H24 -> 0 | J34: =AVERAGE(J24,J25)*0.8 -> #DIV/0! | K34: =AVERAGE(J24,J25)*1.2 -> #DIV/0! | M34: =C14 -> 2402.8789
A36: Sample | D36: =D22 -> Codeine Results | I36: =I22 -> Qualifier (300.2 -> 215.1) Method | J36: =J22 -> Qualifier (300.2 -> 215.1) Results | L36: =L22 -> Codeine D3 (ISTD) Results
A37: Name | B37: Data File | C37: Acq. Date-Time | D37: RT | E37: Resp. | F37: MI | G37: S/N | H37: RR | I37: Rel. Resp. From LRL | J37: Ratio | K37: MI | L37: RT | M37: Resp. | N37: S/N | O37: Detect/ND | Q37: RT PASS? | R37: ANALYTE RESP. PASS? | S37: IS PASS? | T37: RR PASS? | U37: Qual Ion Ratio <0 | V37: All criteria met?
O38: =IF(V38="PASS","DETECT",IF(AND(Q38="Y",R38="Y",S38="N",T38="Y",U38="Y"),"Detect with IS Supp","ND")) -> #DIV/0! | Q38: =IF(AND(D38<($D$32+0.1),D38>($D$32-0.1)),"Y","N") -> Y | R38: =IF(E38>$E$34,"Y","N") -> N | S38: =IF(M38>$M$34,"Y","N") -> N | T38: =IF(H38>$H$34,"Y","N") -> N | U38: =IF(AND(J38>=$J$34, J38<=$K$34), "Y","N") -> #DIV/0! | V38: =IF(AND(Q38="Y",R38="Y",S38="Y",T38="Y",U38="Y"), "PASS","FAIL") -> #DIV/0!
O39: =IF(V39="PASS","DETECT",IF(AND(Q39="Y",R39="Y",S39="N",T39="Y",U39="Y"),"Detect with IS Supp","ND")) -> #DIV/0! | Q39: =IF(AND(D39<($D$32+0.1),D39>($D$32-0.1)),"Y","N") -> Y | R39: =IF(E39>$E$34,"Y","N") -> N | S39: =IF(M39>$M$34,"Y","N") -> N | T39: =IF(H39>$H$34,"Y","N") -> N | U39: =IF(AND(J39>=$J$34, J39<=$K$34), "Y","N") -> #DIV/0! | V39: =IF(AND(Q39="Y",R39="Y",S39="Y",T39="Y",U39="Y"), "PASS","FAIL") -> #DIV/0!
O40: =IF(V40="PASS","DETECT",IF(AND(Q40="Y",R40="Y",S40="N",T40="Y",U40="Y"),"Detect with IS Supp","ND")) -> #DIV/0! | Q40: =IF(AND(D40<($D$32+0.1),D40>($D$32-0.1)),"Y","N") -> Y | R40: =IF(E40>$E$34,"Y","N") -> N | S40: =IF(M40>$M$34,"Y","N") -> N | T40: =IF(H40>$H$34,"Y","N") -> N | U40: =IF(AND(J40>=$J$34, J40<=$K$34), "Y","N") -> #DIV/0! | V40: =IF(AND(Q40="Y",R40="Y",S40="Y",T40="Y",U40="Y"), "PASS","FAIL") -> #DIV/0!
O41: =IF(V41="PASS","DETECT",IF(AND(Q41="Y",R41="Y",S41="N",T41="Y",U41="Y"),"Detect with IS Supp","ND")) -> #DIV/0! | Q41: =IF(AND(D41<($D$32+0.1),D41>($D$32-0.1)),"Y","N") -> Y | R41: =IF(E41>$E$34,"Y","N") -> N | S41: =IF(M41>$M$34,"Y","N") -> N | T41: =IF(H41>$H$34,"Y","N") -> N | U41: =IF(AND(J41>=$J$34, J41<=$K$34), "Y","N") -> #DIV/0! | V41: =IF(AND(Q41="Y",R41="Y",S41="Y",T41="Y",U41="Y"), "PASS","FAIL") -> #DIV/0!
O42: =IF(V42="PASS","DETECT",IF(AND(Q42="Y",R42="Y",S42="N",T42="Y",U42="Y"),"Detect with IS Supp","ND")) -> #DIV/0! | Q42: =IF(AND(D42<($D$32+0.1),D42>($D$32-0.1)),"Y","N") -> Y | R42: =IF(E42>$E$34,"Y","N") -> N | S42: =IF(M42>$M$34,"Y","N") -> N | T42: =IF(H42>$H$34,"Y","N") -> N | U42: =IF(AND(J42>=$J$34, J42<=$K$34), "Y","N") -> #DIV/0! | V42: =IF(AND(Q42="Y",R42="Y",S42="Y",T42="Y",U42="Y"), "PASS","FAIL") -> #DIV/0!
O43: =IF(V43="PASS","DETECT",IF(AND(Q43="Y",R43="Y",S43="N",T43="Y",U43="Y"),"Detect with IS Supp","ND")) -> #DIV/0! | Q43: =IF(AND(D43<($D$32+0.1),D43>($D$32-0.1)),"Y","N") -> Y | R43: =IF(E43>$E$34,"Y","N") -> N | S43: =IF(M43>$M$34,"Y","N") -> N | T43: =IF(H43>$H$34,"Y","N") -> N | U43: =IF(AND(J43>=$J$34, J43<=$K$34), "Y","N") -> #DIV/0! | V43: =IF(AND(Q43="Y",R43="Y",S43="Y",T43="Y",U43="Y"), "PASS","FAIL") -> #DIV/0!
O44: =IF(V44="PASS","DETECT",IF(AND(Q44="Y",R44="Y",S44="N",T44="Y",U44="Y"),"Detect with IS Supp","ND")) -> #DIV/0! | Q44: =IF(AND(D44<($D$32+0.1),D44>($D$32-0.1)),"Y","N") -> Y | R44: =IF(E44>$E$34,"Y","N") -> N | S44: =IF(M44>$M$34,"Y","N") -> N | T44: =IF(H44>$H$34,"Y","N") -> N | U44: =IF(AND(J44>=$J$34, J44<=$K$34), "Y","N") -> #DIV/0! | V44: =IF(AND(Q44="Y",R44="Y",S44="Y",T44="Y",U44="Y"), "PASS","FAIL") -> #DIV/0!
O45: =IF(V45="PASS","DETECT",IF(AND(Q45="Y",R45="Y",S45="N",T45="Y",U45="Y"),"Detect with IS Supp","ND")) -> #DIV/0! | Q45: =IF(AND(D45<($D$32+0.1),D45>($D$32-0.1)),"Y","N") -> Y | R45: =IF(E45>$E$34,"Y","N") -> N | S45: =IF(M45>$M$34,"Y","N") -> N | T45: =IF(H45>$H$34,"Y","N") -> N | U45: =IF(AND(J45>=$J$34, J45<=$K$34), "Y","N") -> #DIV/0! | V45: =IF(AND(Q45="Y",R45="Y",S45="Y",T45="Y",U45="Y"), "PASS","FAIL") -> #DIV/0!
O46: =IF(V46="PASS","DETECT",IF(AND(Q46="Y",R46="Y",S46="N",T46="Y",U46="Y"),"Detect with IS Supp","ND")) -> #DIV/0! | Q46: =IF(AND(D46<($D$32+0.1),D46>($D$32-0.1)),"Y","N") -> Y | R46: =IF(E46>$E$34,"Y","N") -> N | S46: =IF(M46>$M$34,"Y","N") -> N | T46: =IF(H46>$H$34,"Y","N") -> N | U46: =IF(AND(J46>=$J$34, J46<=$K$34), "Y","N") -> #DIV/0! | V46: =IF(AND(Q46="Y",R46="Y",S46="Y",T46="Y",U46="Y"), "PASS","FAIL") -> #DIV/0!
...

Sheet Amphetamine
A1: Amphetamine
A4: =Codeine!A4 -> Method/SOP | D4: =Codeine!D4 -> Column Lot #: | H4: =Codeine!H4 -> Urine Lot #: | J4: =Codeine!J4 -> Standards Date:
A5: =Codeine!A5 -> Batch ID: | D5: =Codeine!D5 -> Instrument: | H5: =Codeine!H5 -> Analyst: | J5: =Codeine!J5 -> Reviewer:
A7: QC Criteria
A8: Paste LRL and QCH Results in the light blue shaded areas. Paste LRL results in row 17 and QCH results in row 18.
A10: QC Low (LRL) | B10: Response | F10: Retention Time | I10: QC High | J10: Response | N10: Retention Time
B11: 25% of Lowest | D11: Run Value | E11: Pass/Fail | F11: Characterization | H11: Run Value | J11: 25% of Lowest | L11: Run Value | M11: Pass/Fail | N11: Characterization | P11: Run Value
B12: Analytical | C12: 111899.25 | D12: =E24 -> 0 | E12: =IF(D12>C12,"PASS","FAIL") -> FAIL | F12: Avg | G12: =$D$24 -> 0 | H12: =D24 -> 0 | J12: Analytical | K12: 281556.5 | L12: =E25 -> 0 | M12: =IF(L12>K12,"PASS","FAIL") -> FAIL | N12: Avg | O12: =$D$24 -> 0 | P12: =D25 -> 0
B13: Qualifier | C13: 10.666411 | D13: =J24 -> 0 | E13: =IF(D13>C13,"PASS","FAIL") -> FAIL | F13: 0.1 | G13: =G12+0.1 -> 0.1 | H13: Pass/Fail | J13: Qualifier | K13: 10.693407 | L13: =J25 -> 0 | M13: =IF(L13>K13,"PASS","FAIL") -> FAIL | N13: 0.1 | O13: =O12+0.1 -> 0.1 | P13: Pass/Fail
B14: IS | C14: 82640.46 | D14: =M24 -> 0 | E14: =IF(D14>C14,"PASS","FAIL") -> FAIL | F14: -0.1 | G14: =G12-0.1 -> -0.1 | H14: =IF(AND(H12>G14,H12<G13),"PASS","FAIL") -> PASS | J14: IS | K14: 74113 | L14: =M25 -> 0 | M14: =IF(L14>K14,"PASS","FAIL") -> FAIL | N14: -0.1 | O14: =O12-0.1 -> -0.1 | P14: =IF(AND(P12>O14,P12<O13),"PASS","FAIL") -> PASS
A16: QC Low (LRL) | B16: Response | F16: Retention Time | I16: QC High | J16: Response | N16: Retention Time
B17: 25% of Lowest | D17: Run Value | E17: Pass/Fail | F17: Characterization | H17: Run Value | J17: 25% of Lowest | L17: Run Value | M17: Pass/Fail | N17: Characterization | P17: Run Value
B18: Analytical | C18: 111899.25 | D18: =E26 -> 0 | E18: =IF(D18>C18,"PASS","FAIL") -> FAIL | F18: Avg | G18: =$D$24 -> 0 | H18: =D26 -> 0 | J18: Analytical | K18: 281556.5 | L18: =E27 -> 0 | M18: =IF(L18>K18,"PASS","FAIL") -> FAIL | N18: Avg | O18: =$D$24 -> 0 | P18: =D27 -> 0
B19: Qualifier | C19: 10.666411 | D19: =J26 -> 0 | E19: =IF(D19>C19,"PASS","FAIL") -> FAIL | F19: 0.1 | G19: =G18+0.1 -> 0.1 | H19: Pass/Fail | J19: Qualifier | K19: 10.693407 | L19: =J27 -> 0 | M19: =IF(L19>K19,"PASS","FAIL") -> FAIL | N19: 0.1 | O19: =O18+0.1 -> 0.1 | P19: Pass/Fail
B20: IS | C20: 82640.46 | D20: =M26 -> 0 | E20: =IF(D20>C20,"PASS","FAIL") -> FAIL | F20: -0.1 | G20: =G18-0.1 -> -0.1 | H20: =IF(AND(H18>G20,H18<G19),"PASS","FAIL") -> PASS | J20: IS | K20: 74113 | L20: =M27 -> 0 | M20: =IF(L20>K20,"PASS","FAIL") -> FAIL | N20: -0.1 | O20: =O18-0.1 -> -0.1 | P20: =IF(AND(P18>O20,P18<O19),"PASS","FAIL") -> PASS
A22: Sample | D22: =D60 -> Amphetamine Results | I22: =I60 -> Qualifier (136.1 -> 119.0) Method | J22: =J60 -> Qualifier (136.1 -> 119.0) Results | L22: =L60 -> Amphetamine D5 (ISTD) Results
A23: Name | B23: Data File | C23: Acq. Date-Time | D23: RT | E23: Resp. | F23: MI | G23: S/N | H23: RR | I23: Rel. Resp. | J23: Ratio | K23: MI | L23: RT | M23: Resp. | N23: S/N
A24: Opening QCL
A25: Opening QCH
A26: Closing QCL
A27: Closing QCH
A29: Sample Criteria | Q29: Sample Criteria QC
A30: Paste Sample Results in the light orange shaded areas.If more than 10 samples were analyzed in the bracket, add rows and drag down formulas. Conditional formatting will highlight RED if the sample fails for the criteria and GREEN if it passes for the criteria. All criteria must be GREEN for a sample to be considered a DETECT.
A31: 20 Samples between QCs? | B31: Yes | C31: 1. Retention Time | E31: 2. Analyte Response | H31: 3. Resp. Ratio | I31: 4. Qualifier | M31: 5. ISTD | O31: Sample Result
C32: Avg In-Run RT | D32: =$D$24 -> 0 | E32: In-Run QCL Response Threshold | H32: In-Run QCL RR | J32: Qualifier Ion Ratio Limits | M32: Response Threshold
C33: RT Limits | D33: =D32-0.1 -> -0.1
D34: =(D32+0.1) -> 0.1 | E34: =E24 -> 0 | H34: =H24 -> 0 | J34: =AVERAGE(J24,J25)*0.8 -> #DIV/0! | K34: =AVERAGE(J24,J25)*1.2 -> #DIV/0! | M34: =C14 -> 82640.46
A36: Sample | D36: =D22 -> Amphetamine Results | I36: =I22 -> Qualifier (136.1 -> 119.0) Method | J36: =J22 -> Qualifier (136.1 -> 119.0) Results | L36: =L22 -> Amphetamine D5 (ISTD) Results
A37: Name | B37: Data File | C37: Acq. Date-Time | D37: RT | E37: Resp. | F37: MI | G37: S/N | H37: RR | I37: Rel. Resp. From LRL | J37: Ratio | K37: MI | L37: RT | M37: Resp. | N37: S/N | O37: Detect/ND | Q37: RT PASS? | R37: ANALYTE RESP. PASS? | S37: IS PASS? | T37: RR PASS? | U37: Qual Ion Ratio <0 | V37: All criteria met?
O38: =IF(V38="PASS","DETECT",IF(AND(Q38="Y",R38="Y",S38="N",T38="Y",U38="Y"),"Detect with IS Supp","ND")) -> #DIV/0! | Q38: =IF(AND(D38<($D$32+0.1),D38>($D$32-0.1)),"Y","N") -> Y | R38: =IF(E38>$E$34,"Y","N") -> N | S38: =IF(M38>$M$34,"Y","N") -> N | T38: =IF(H38>$H$34,"Y","N") -> N | U38: =IF(AND(J38>=$J$34, J38<=$K$34), "Y","N") -> #DIV/0! | V38: =IF(AND(Q38="Y",R38="Y",S38="Y",T38="Y",U38="Y"), "PASS","FAIL") -> #DIV/0!
O39: =IF(V39="PASS","DETECT",IF(AND(Q39="Y",R39="Y",S39="N",T39="Y",U39="Y"),"Detect with IS Supp","ND")) -> #DIV/0! | Q39: =IF(AND(D39<($D$32+0.1),D39>($D$32-0.1)),"Y","N") -> Y | R39: =IF(E39>$E$34,"Y","N") -> N | S39: =IF(M39>$M$34,"Y","N") -> N | T39: =IF(H39>$H$34,"Y","N") -> N | U39: =IF(AND(J39>=$J$34, J39<=$K$34), "Y","N") -> #DIV/0! | V39: =IF(AND(Q39="Y",R39="Y",S39="Y",T39="Y",U39="Y"), "PASS","FAIL") -> #DIV/0!
O40: =IF(V40="PASS","DETECT",IF(AND(Q40="Y",R40="Y",S40="N",T40="Y",U40="Y"),"Detect with IS Supp","ND")) -> #DIV/0! | Q40: =IF(AND(D40<($D$32+0.1),D40>($D$32-0.1)),"Y","N") -> Y | R40: =IF(E40>$E$34,"Y","N") -> N | S40: =IF(M40>$M$34,"Y","N") -> N | T40: =IF(H40>$H$34,"Y","N") -> N | U40: =IF(AND(J40>=$J$34, J40<=$K$34), "Y","N") -> #DIV/0! | V40: =IF(AND(Q40="Y",R40="Y",S40="Y",T40="Y",U40="Y"), "PASS","FAIL") -> #DIV/0!
O41: =IF(V41="PASS","DETECT",IF(AND(Q41="Y",R41="Y",S41="N",T41="Y",U41="Y"),"Detect with IS Supp","ND")) -> #DIV/0! | Q41: =IF(AND(D41<($D$32+0.1),D41>($D$32-0.1)),"Y","N") -> Y | R41: =IF(E41>$E$34,"Y","N") -> N | S41: =IF(M41>$M$34,"Y","N") -> N | T41: =IF(H41>$H$34,"Y","N") -> N | U41: =IF(AND(J41>=$J$34, J41<=$K$34), "Y","N") -> #DIV/0! | V41: =IF(AND(Q41="Y",R41="Y",S41="Y",T41="Y",U41="Y"), "PASS","FAIL") -> #DIV/0!
O42: =IF(V42="PASS","DETECT",IF(AND(Q42="Y",R42="Y",S42="N",T42="Y",U42="Y"),"Detect with IS Supp","ND")) -> #DIV/0! | Q42: =IF(AND(D42<($D$32+0.1),D42>($D$32-0.1)),"Y","N") -> Y | R42: =IF(E42>$E$34,"Y","N") -> N | S42: =IF(M42>$M$34,"Y","N") -> N | T42: =IF(H42>$H$34,"Y","N") -> N | U42: =IF(AND(J42>=$J$34, J42<=$K$34), "Y","N") -> #DIV/0! | V42: =IF(AND(Q42="Y",R42="Y",S42="Y",T42="Y",U42="Y"), "PASS","FAIL") -> #DIV/0!
O43: =IF(V43="PASS","DETECT",IF(AND(Q43="Y",R43="Y",S43="N",T43="Y",U43="Y"),"Detect with IS Supp","ND")) -> #DIV/0! | Q43: =IF(AND(D43<($D$32+0.1),D43>($D$32-0.1)),"Y","N") -> Y | R43: =IF(E43>$E$34,"Y","N") -> N | S43: =IF(M43>$M$34,"Y","N") -> N | T43: =IF(H43>$H$34,"Y","N") -> N | U43: =IF(AND(J43>=$J$34, J43<=$K$34), "Y","N") -> #DIV/0! | V43: =IF(AND(Q43="Y",R43="Y",S43="Y",T43="Y",U43="Y"), "PASS","FAIL") -> #DIV/0!
O44: =IF(V44="PASS","DETECT",IF(AND(Q44="Y",R44="Y",S44="N",T44="Y",U44="Y"),"Detect with IS Supp","ND")) -> #DIV/0! | Q44: =IF(AND(D44<($D$32+0.1),D44>($D$32-0.1)),"Y","N") -> Y | R44: =IF(E44>$E$34,"Y","N") -> N | S44: =IF(M44>$M$34,"Y","N") -> N | T44: =IF(H44>$H$34,"Y","N") -> N | U44: =IF(AND(J44>=$J$34, J44<=$K$34), "Y","N") -> #DIV/0! | V44: =IF(AND(Q44="Y",R44="Y",S44="Y",T44="Y",U44="Y"), "PASS","FAIL") -> #DIV/0!
O45: =IF(V45="PASS","DETECT",IF(AND(Q45="Y",R45="Y",S45="N",T45="Y",U45="Y"),"Detect with IS Supp","ND")) -> #DIV/0! | Q45: =IF(AND(D45<($D$32+0.1),D45>($D$32-0.1)),"Y","N") -> Y | R45: =IF(E45>$E$34,"Y","N") -> N | S45: =IF(M45>$M$34,"Y","N") -> N | T45: =IF(H45>$H$34,"Y","N") -> N | U45: =IF(AND(J45>=$J$34, J45<=$K$34), "Y","N") -> #DIV/0! | V45: =IF(AND(Q45="Y",R45="Y",S45="Y",T45="Y",U45="Y"), "PASS","FAIL") -> #DIV/0!
O46: =IF(V46="PASS","DETECT",IF(AND(Q46="Y",R46="Y",S46="N",T46="Y",U46="Y"),"Detect with IS Supp","ND")) -> #DIV/0! | Q46: =IF(AND(D46<($D$32+0.1),D46>($D$32-0.1)),"Y","N") -> Y | R46: =IF(E46>$E$34,"Y","N") -> N | S46: =IF(M46>$M$34,"Y","N") -> N | T46: =IF(H46>$H$34,"Y","N") -> N | U46: =IF(AND(J46>=$J$34, J46<=$K$34), "Y","N") -> #DIV/0! | V46: =IF(AND(Q46="Y",R46="Y",S46="Y",T46="Y",U46="Y"), "PASS","FAIL") -> #DIV/0!
O47: =IF(V47="PASS","DETECT",IF(AND(Q47="Y",R47="Y",S47="N",T47="Y",U47="Y"),"Detect with IS Supp","ND")) -> #DIV/0! | Q47: =IF(AND(D47<($D$32+0.1),D47>($D$32-0.1)),"Y","N") -> Y | R47: =IF(E47>$E$34,"Y","N") -> N | S47: =IF(M47>$M$34,"Y","N") -> N | T47: =IF(H47>$H$34,"Y","N") -> N | U47: =IF(AND(J47>=$J$34, J47<=$K$34), "Y","N") -> #DIV/0! | V47: =IF(AND(Q47="Y",R47="Y",S47="Y",T47="Y",U47="Y"), "PASS","FAIL") -> #DIV/0!
O48: =IF(V48="PASS","DETECT",IF(AND(Q48="Y",R48="Y",S48="N",T48="Y",U48="Y"),"Detect with IS Supp","ND")) -> #DIV/0! | Q48: =IF(AND(D48<($D$32+0.1),D48>($D$32-0.1)),"Y","N") -> Y | R48: =IF(E48>$E$34,"Y","N") -> N | S48: =IF(M48>$M$34,"Y","N") -> N | T48: =IF(H48>$H$34,"Y","N") -> N | U48: =IF(AND(J48>=$J$34, J48<=$K$34), "Y","N") -> #DIV/0! | V48: =IF(AND(Q48="Y",R48="Y",S48="Y",T48="Y",U48="Y"), "PASS","FAIL") -> #DIV/0!
...

Sheet Norfentanyl
A1: Norfentanyl
A4: =Codeine!A4 -> Method/SOP | D4: =Codeine!D4 -> Column Lot #: | H4: =Codeine!H4 -> Urine Lot #: | J4: =Codeine!J4 -> Standards Date:
A5: =Codeine!A5 -> Batch ID: | D5: =Codeine!D5 -> Instrument: | H5: =Codeine!H5 -> Analyst: | J5: =Codeine!J5 -> Reviewer:
A7: QC Criteria
A8: Paste LRL and QCH Results in the light blue shaded areas. Paste LRL results in row 17 and QCH results in row 18.
A10: QC Low (LRL) | B10: Response | F10: Retention Time | I10: QC High | J10: Response | N10: Retention Time
B11: 25% of Lowest | D11: Run Value | E11: Pass/Fail | F11: Characterization | H11: Run Value | J11: 25% of Lowest | L11: Run Value | M11: Pass/Fail | N11: Characterization | P11: Run Value
B12: Analytical | C12: 3579.0922 | D12: =E24 -> 0 | E12: =IF(D12>C12,"PASS","FAIL") -> FAIL | F12: Avg | G12: =$D$24 -> 0 | H12: =D24 -> 0 | J12: Analytical | K12: 78978.635 | L12: =E25 -> 0 | M12: =IF(L12>K12,"PASS","FAIL") -> FAIL | N12: Avg | O12: =$D$24 -> 0 | P12: =D25 -> 0
B13: Qualifier | C13: 96.312871 | D13: =J24 -> 0 | E13: =IF(D13>C13,"PASS","FAIL") -> FAIL | F13: 0.1 | G13: =G12+0.1 -> 0.1 | H13: Pass/Fail | J13: Qualifier | K13: 97.275 | L13: =J25 -> 0 | M13: =IF(L13>K13,"PASS","FAIL") -> FAIL | N13: 0.1 | O13: =O12+0.1 -> 0.1 | P13: Pass/Fail
B14: IS | C14: 55805.874 | D14: =M24 -> 0 | E14: =IF(D14>C14,"PASS","FAIL") -> FAIL | F14: -0.1 | G14: =G12-0.1 -> -0.1 | H14: =IF(AND(H12>G14,H12<G13),"PASS","FAIL") -> PASS | J14: IS | K14: 55871 | L14: =M25 -> 0 | M14: =IF(L14>K14,"PASS","FAIL") -> FAIL | N14: -0.1 | O14: =O12-0.1 -> -0.1 | P14: =IF(AND(P12>O14,P12<O13),"PASS","FAIL") -> PASS
A16: QC Low (LRL) | B16: Response | F16: Retention Time | I16: QC High | J16: Response | N16: Retention Time
B17: 25% of Lowest | D17: Run Value | E17: Pass/Fail | F17: Characterization | H17: Run Value | J17: 25% of Lowest | L17: Run Value | M17: Pass/Fail | N17: Characterization | P17: Run Value
B18: Analytical | C18: 3579.0922 | D18: =E26 -> 0 | E18: =IF(D18>C18,"PASS","FAIL") -> FAIL | F18: Avg | G18: =$D$24 -> 0 | H18: =D26 -> 0 | J18: Analytical | K18: 78978.635 | L18: =E27 -> 0 | M18: =IF(L18>K18,"PASS","FAIL") -> FAIL | N18: Avg | O18: =$D$24 -> 0 | P18: =D27 -> 0
B19: Qualifier | C19: 96.312871 | D19: =J26 -> 0 | E19: =IF(D19>C19,"PASS","FAIL") -> FAIL | F19: 0.1 | G19: =G18+0.1 -> 0.1 | H19: Pass/Fail | J19: Qualifier | K19: 97.275 | L19: =J27 -> 0 | M19: =IF(L19>K19,"PASS","FAIL") -> FAIL | N19: 0.1 | O19: =O18+0.1 -> 0.1 | P19: Pass/Fail
B20: IS | C20: 55805.874 | D20: =M26 -> 0 | E20: =IF(D20>C20,"PASS","FAIL") -> FAIL | F20: -0.1 | G20: =G18-0.1 -> -0.1 | H20: =IF(AND(H18>G20,H18<G19),"PASS","FAIL") -> PASS | J20: IS | K20: 55871 | L20: =M27 -> 0 | M20: =IF(L20>K20,"PASS","FAIL") -> FAIL | N20: -0.1 | O20: =O18-0.1 -> -0.1 | P20: =IF(AND(P18>O20,P18<O19),"PASS","FAIL") -> PASS
A22: Sample | D22: =D60 -> Norfentanyl Results | I22: =I60 -> Qualifier (233.2 -> 84.1) Method | J22: =J60 -> Qualifier (233.2 -> 84.1) Results | L22: =L60 -> Norfentanyl D5 (ISTD) Results
A23: Name | B23: Data File | C23: Acq. Date-Time | D23: RT | E23: Resp. | F23: MI | G23: S/N | H23: RR | I23: Rel. Resp. | J23: Ratio | K23: MI | L23: RT | M23: Resp. | N23: S/N
A24: Opening QCL
A25: Opening QCH
A26: Closing QCL
A27: Closing QCH
A29: Sample Criteria | Q29: Sample Criteria QC
A30: Paste Sample Results in the light orange shaded areas.If more than 10 samples were analyzed in the bracket, add rows and drag down formulas. Conditional formatting will highlight RED if the sample fails for the criteria and GREEN if it passes for the criteria. All criteria must be GREEN for a sample to be considered a DETECT.
A31: 20 Samples between QCs? | B31: Yes | C31: 1. Retention Time | E31: 2. Analyte Response | H31: 3. Resp. Ratio | I31: 4. Qualifier | M31: 5. ISTD | O31: Sample Result
C32: Avg In-Run RT | D32: =$D$24 -> 0 | E32: In-Run QCL Response Threshold | H32: In-Run QCL RR | J32: Qualifier Ion Ratio Limits | M32: Response Threshold
C33: RT Limits | D33: =D32-0.1 -> -0.1
D34: =(D32+0.1) -> 0.1 | E34: =E24 -> 0 | H34: =H24 -> 0 | J34: =AVERAGE(J24,J25)*0.8 -> #DIV/0! | K34: =AVERAGE(J24,J25)*1.2 -> #DIV/0! | M34: =C14 -> 55805.874
A36: Sample | D36: =D22 -> Norfentanyl Results | I36: =I22 -> Qualifier (233.2 -> 84.1) Method | J36: =J22 -> Qualifier (233.2 -> 84.1) Results | L36: =L22 -> Norfentanyl D5 (ISTD) Results
A37: Name | B37: Data File | C37: Acq. Date-Time | D37: RT | E37: Resp. | F37: MI | G37: S/N | H37: RR | I37: Rel. Resp. From LRL | J37: Ratio | K37: MI | L37: RT | M37: Resp. | N37: S/N | O37: Detect/ND | Q37: RT PASS? | R37: ANALYTE RESP. PASS? | S37: IS PASS? | T37: RR PASS? | U37: Qual Ion Ratio <0 | V37: All criteria met?
O38: =IF(V38="PASS","DETECT",IF(AND(Q38="Y",R38="Y",S38="N",T38="Y",U38="Y"),"Detect with IS Supp","ND")) -> #DIV/0! | Q38: =IF(AND(D38<($D$32+0.1),D38>($D$32-0.1)),"Y","N") -> Y | R38: =IF(E38>$E$34,"Y","N") -> N | S38: =IF(M38>$M$34,"Y","N") -> N | T38: =IF(H38>$H$34,"Y","N") -> N | U38: =IF(AND(J38>=$J$34, J38<=$K$34), "Y","N") -> #DIV/0! | V38: =IF(AND(Q38="Y",R38="Y",S38="Y",T38="Y",U38="Y"), "PASS","FAIL") -> #DIV/0!
O39: =IF(V39="PASS","DETECT",IF(AND(Q39="Y",R39="Y",S39="N",T39="Y",U39="Y"),"Detect with IS Supp","ND")) -> #DIV/0! | Q39: =IF(AND(D39<($D$32+0.1),D39>($D$32-0.1)),"Y","N") -> Y | R39: =IF(E39>$E$34,"Y","N") -> N | S39: =IF(M39>$M$34,"Y","N") -> N | T39: =IF(H39>$H$34,"Y","N") -> N | U39: =IF(AND(J39>=$J$34, J39<=$K$34), "Y","N") -> #DIV/0! | V39: =IF(AND(Q39="Y",R39="Y",S39="Y",T39="Y",U39="Y"), "PASS","FAIL") -> #DIV/0!
O40: =IF(V40="PASS","DETECT",IF(AND(Q40="Y",R40="Y",S40="N",T40="Y",U40="Y"),"Detect with IS Supp","ND")) -> #DIV/0! | Q40: =IF(AND(D40<($D$32+0.1),D40>($D$32-0.1)),"Y","N") -> Y | R40: =IF(E40>$E$34,"Y","N") -> N | S40: =IF(M40>$M$34,"Y","N") -> N | T40: =IF(H40>$H$34,"Y","N") -> N | U40: =IF(AND(J40>=$J$34, J40<=$K$34), "Y","N") -> #DIV/0! | V40: =IF(AND(Q40="Y",R40="Y",S40="Y",T40="Y",U40="Y"), "PASS","FAIL") -> #DIV/0!
O41: =IF(V41="PASS","DETECT",IF(AND(Q41="Y",R41="Y",S41="N",T41="Y",U41="Y"),"Detect with IS Supp","ND")) -> #DIV/0! | Q41: =IF(AND(D41<($D$32+0.1),D41>($D$32-0.1)),"Y","N") -> Y | R41: =IF(E41>$E$34,"Y","N") -> N | S41: =IF(M41>$M$34,"Y","N") -> N | T41: =IF(H41>$H$34,"Y","N") -> N | U41: =IF(AND(J41>=$J$34, J41<=$K$34), "Y","N") -> #DIV/0! | V41: =IF(AND(Q41="Y",R41="Y",S41="Y",T41="Y",U41="Y"), "PASS","FAIL") -> #DIV/0!
O42: =IF(V42="PASS","DETECT",IF(AND(Q42="Y",R42="Y",S42="N",T42="Y",U42="Y"),"Detect with IS Supp","ND")) -> #DIV/0! | Q42: =IF(AND(D42<($D$32+0.1),D42>($D$32-0.1)),"Y","N") -> Y | R42: =IF(E42>$E$34,"Y","N") -> N | S42: =IF(M42>$M$34,"Y","N") -> N | T42: =IF(H42>$H$34,"Y","N") -> N | U42: =IF(AND(J42>=$J$34, J42<=$K$34), "Y","N") -> #DIV/0! | V42: =IF(AND(Q42="Y",R42="Y",S42="Y",T42="Y",U42="Y"), "PASS","FAIL") -> #DIV/0!
O43: =IF(V43="PASS","DETECT",IF(AND(Q43="Y",R43="Y",S43="N",T43="Y",U43="Y"),"Detect with IS Supp","ND")) -> #DIV/0! | Q43: =IF(AND(D43<($D$32+0.1),D43>($D$32-0.1)),"Y","N") -> Y | R43: =IF(E43>$E$34,"Y","N") -> N | S43: =IF(M43>$M$34,"Y","N") -> N | T43: =IF(H43>$H$34,"Y","N") -> N | U43: =IF(AND(J43>=$J$34, J43<=$K$34), "Y","N") -> #DIV/0! | V43: =IF(AND(Q43="Y",R43="Y",S43="Y",T43="Y",U43="Y"), "PASS","FAIL") -> #DIV/0!
O44: =IF(V44="PASS","DETECT",IF(AND(Q44="Y",R44="Y",S44="N",T44="Y",U44="Y"),"Detect with IS Supp","ND")) -> #DIV/0! | Q44: =IF(AND(D44<($D$32+0.1),D44>($D$32-0.1)),"Y","N") -> Y | R44: =IF(E44>$E$34,"Y","N") -> N | S44: =IF(M44>$M$34,"Y","N") -> N | T44: =IF(H44>$H$34,"Y","N") -> N | U44: =IF(AND(J44>=$J$34, J44<=$K$34), "Y","N") -> #DIV/0! | V44: =IF(AND(Q44="Y",R44="Y",S44="Y",T44="Y",U44="Y"), "PASS","FAIL") -> #DIV/0!
O45: =IF(V45="PASS","DETECT",IF(AND(Q45="Y",R45="Y",S45="N",T45="Y",U45="Y"),"Detect with IS Supp","ND")) -> #DIV/0! | Q45: =IF(AND(D45<($D$32+0.1),D45>($D$32-0.1)),"Y","N") -> Y | R45: =IF(E45>$E$34,"Y","N") -> N | S45: =IF(M45>$M$34,"Y","N") -> N | T45: =IF(H45>$H$34,"Y","N") -> N | U45: =IF(AND(J45>=$J$34, J45<=$K$34), "Y","N") -> #DIV/0! | V45: =IF(AND(Q45="Y",R45="Y",S45="Y",T45="Y",U45="Y"), "PASS","FAIL") -> #DIV/0!
O46: =IF(V46="PASS","DETECT",IF(AND(Q46="Y",R46="Y",S46="N",T46="Y",U46="Y"),"Detect with IS Supp","ND")) -> #DIV/0! | Q46: =IF(AND(D46<($D$32+0.1),D46>($D$32-0.1)),"Y","N") -> Y | R46: =IF(E46>$E$34,"Y","N") -> N | S46: =IF(M46>$M$34,"Y","N") -> N | T46: =IF(H46>$H$34,"Y","N") -> N | U46: =IF(AND(J46>=$J$34, J46<=$K$34), "Y","N") -> #DIV/0! | V46: =IF(AND(Q46="Y",R46="Y",S46="Y",T46="Y",U46="Y"), "PASS","FAIL") -> #DIV/0!
O47: =IF(V47="PASS","DETECT",IF(AND(Q47="Y",R47="Y",S47="N",T47="Y",U47="Y"),"Detect with IS Supp","ND")) -> #DIV/0! | Q47: =IF(AND(D47<($D$32+0.1),D47>($D$32-0.1)),"Y","N") -> Y | R47: =IF(E47>$E$34,"Y","N") -> N | S47: =IF(M47>$M$34,"Y","N") -> N | T47: =IF(H47>$H$34,"Y","N") -> N | U47: =IF(AND(J47>=$J$34, J47<=$K$34), "Y","N") -> #DIV/0! | V47: =IF(AND(Q47="Y",R47="Y",S47="Y",T47="Y",U47="Y"), "PASS","FAIL") -> #DIV/0!
O48: =IF(V48="PASS","DETECT",IF(AND(Q48="Y",R48="Y",S48="N",T48="Y",U48="Y"),"Detect with IS Supp","ND")) -> #DIV/0! | Q48: =IF(AND(D48<($D$32+0.1),D48>($D$32-0.1)),"Y","N") -> Y | R48: =IF(E48>$E$34,"Y","N") -> N | S48: =IF(M48>$M$34,"Y","N") -> N | T48: =IF(H48>$H$34,"Y","N") -> N | U48: =IF(AND(J48>=$J$34, J48<=$K$34), "Y","N") -> #DIV/0! | V48: =IF(AND(Q48="Y",R48="Y",S48="Y",T48="Y",U48="Y"), "PASS","FAIL") -> #DIV/0!
...

Sheet Norcarfentanil
A1: Norcarfentanil
A4: =Codeine!A4 -> Method/SOP | D4: =Codeine!D4 -> Column Lot #: | H4: =Codeine!H4 -> Urine Lot #: | J4: =Codeine!J4 -> Standards Date:
A5: =Codeine!A5 -> Batch ID: | D5: =Codeine!D5 -> Instrument: | H5: =Codeine!H5 -> Analyst: | J5: =Codeine!J5 -> Reviewer:
A7: QC Criteria
A8: Paste LRL and QCH Results in the light blue shaded areas. Paste LRL results in row 17 and QCH results in row 18.
A10: QC Low (LRL) | B10: Response | F10: Retention Time | I10: QC High | J10: Response | N10: Retention Time
B11: 25% of Lowest | D11: Run Value | E11: Pass/Fail | F11: Characterization | H11: Run Value | J11: 25% of Lowest | L11: Run Value | M11: Pass/Fail | N11: Characterization | P11: Run Value
B12: Analytical | C12: 8386.759 | D12: =E24 -> 0 | E12: =IF(D12>C12,"PASS","FAIL") -> FAIL | F12: Avg | G12: =$D$24 -> 0 | H12: =D24 -> 0 | J12: Analytical | K12: 176191.69 | L12: =E25 -> 0 | M12: =IF(L12>K12,"PASS","FAIL") -> FAIL | N12: Avg | O12: =$D$24 -> 0 | P12: =D25 -> 0
B13: Qualifier | C13: 16.637537 | D13: =J24 -> 0 | E13: =IF(D13>C13,"PASS","FAIL") -> FAIL | F13: 0.1 | G13: =G12+0.1 -> 0.1 | H13: Pass/Fail | J13: Qualifier | K13: 18.782985 | L13: =J25 -> 0 | M13: =IF(L13>K13,"PASS","FAIL") -> FAIL | N13: 0.1 | O13: =O12+0.1 -> 0.1 | P13: Pass/Fail
B14: IS | C14: 55805.874 | D14: =M24 -> 0 | E14: =IF(D14>C14,"PASS","FAIL") -> FAIL | F14: -0.1 | G14: =G12-0.1 -> -0.1 | H14: =IF(AND(H12>G14,H12<G13),"PASS","FAIL") -> PASS | J14: IS | K14: 55871.469 | L14: =M25 -> 0 | M14: =IF(L14>K14,"PASS","FAIL") -> FAIL | N14: -0.1 | O14: =O12-0.1 -> -0.1 | P14: =IF(AND(P12>O14,P12<O13),"PASS","FAIL") -> PASS
A16: QC Low (LRL) | B16: Response | F16: Retention Time | I16: QC High | J16: Response | N16: Retention Time
B17: 25% of Lowest | D17: Run Value | E17: Pass/Fail | F17: Characterization | H17: Run Value | J17: 25% of Lowest | L17: Run Value | M17: Pass/Fail | N17: Characterization | P17: Run Value
B18: Analytical | C18: 8386.759 | D18: =E26 -> 0 | E18: =IF(D18>C18,"PASS","FAIL") -> FAIL | F18: Avg | G18: =$D$24 -> 0 | H18: =D26 -> 0 | J18: Analytical | K18: 176191.69 | L18: =E27 -> 0 | M18: =IF(L18>K18,"PASS","FAIL") -> FAIL | N18: Avg | O18: =$D$24 -> 0 | P18: =D27 -> 0
B19: Qualifier | C19: 16.637537 | D19: =J26 -> 0 | E19: =IF(D19>C19,"PASS","FAIL") -> FAIL | F19: 0.1 | G19: =G18+0.1 -> 0.1 | H19: Pass/Fail | J19: Qualifier | K19: 18.782985 | L19: =J27 -> 0 | M19: =IF(L19>K19,"PASS","FAIL") -> FAIL | N19: 0.1 | O19: =O18+0.1 -> 0.1 | P19: Pass/Fail
B20: IS | C20: 55805.874 | D20: =M26 -> 0 | E20: =IF(D20>C20,"PASS","FAIL") -> FAIL | F20: -0.1 | G20: =G18-0.1 -> -0.1 | H20: =IF(AND(H18>G20,H18<G19),"PASS","FAIL") -> PASS | J20: IS | K20: 55871.469 | L20: =M27 -> 0 | M20: =IF(L20>K20,"PASS","FAIL") -> FAIL | N20: -0.1 | O20: =O18-0.1 -> -0.1 | P20: =IF(AND(P18>O20,P18<O19),"PASS","FAIL") -> PASS
A22: Sample | D22: =D60 -> Norcarfentanil Results | I22: =I60 -> Qualifier (291.2 -> 142.1) Method | J22: =J60 -> Qualifier (291.2 -> 142.1) Results | L22: =L60 -> Norfentanyl D5 (ISTD) Results
A23: Name | B23: Data File | C23: Acq. Date-Time | D23: RT | E23: Resp. | F23: MI | G23: S/N | H23: RR | I23: Rel. Resp. | J23: Ratio | K23: MI | L23: RT | M23: Resp. | N23: S/N
A24: Opening QCL
A25: Opening QCH
A26: Closing QCL
A27: Closing QCH
A29: Sample Criteria | Q29: Sample Criteria QC
A30: Paste Sample Results in the light orange shaded areas.If more than 10 samples were analyzed in the bracket, add rows and drag down formulas. Conditional formatting will highlight RED if the sample fails for the criteria and GREEN if it passes for the criteria. All criteria must be GREEN for a sample to be considered a DETECT.
A31: 20 Samples between QCs? | B31: Yes | C31: 1. Retention Time | E31: 2. Analyte Response | H31: 3. Resp. Ratio | I31: 4. Qualifier | M31: 5. ISTD | O31: Sample Result
C32: Avg In-Run RT | D32: =$D$24 -> 0 | E32: In-Run QCL Response Threshold | H32: In-Run QCL RR | J32: Qualifier Ion Ratio Limits | M32: Response Threshold
C33: RT Limits | D33: =D32-0.1 -> -0.1
D34: =(D32+0.1) -> 0.1 | E34: =E24 -> 0 | H34: =H24 -> 0 | J34: =AVERAGE(J24,J25)*0.8 -> #DIV/0! | K34: =AVERAGE(J24,J25)*1.2 -> #DIV/0! | M34: =C14 -> 55805.874
A36: Sample | D36: =D22 -> Norcarfentanil Results | I36: =I22 -> Qualifier (291.2 -> 142.1) Method | J36: =J22 -> Qualifier (291.2 -> 142.1) Results | L36: =L22 -> Norfentanyl D5 (ISTD) Results
A37: Name | B37: Data File | C37: Acq. Date-Time | D37: RT | E37: Resp. | F37: MI | G37: S/N | H37: RR | I37: Rel. Resp. From LRL | J37: Ratio | K37: MI | L37: RT | M37: Resp. | N37: S/N | O37: Detect/ND | Q37: RT PASS? | R37: ANALYTE RESP. PASS? | S37: IS PASS? | T37: RR PASS? | U37: Qual Ion Ratio <0 | V37: All criteria met?
O38: =IF(V38="PASS","DETECT",IF(AND(Q38="Y",R38="Y",S38="N",T38="Y",U38="Y"),"Detect with IS Supp","ND")) -> #DIV/0! | Q38: =IF(AND(D38<($D$32+0.1),D38>($D$32-0.1)),"Y","N") -> Y | R38: =IF(E38>$E$34,"Y","N") -> N | S38: =IF(M38>$M$34,"Y","N") -> N | T38: =IF(H38>$H$34,"Y","N") -> N | U38: =IF(AND(J38>=$J$34, J38<=$K$34), "Y","N") -> #DIV/0! | V38: =IF(AND(Q38="Y",R38="Y",S38="Y",T38="Y",U38="Y"), "PASS","FAIL") -> #DIV/0!
O39: =IF(V39="PASS","DETECT",IF(AND(Q39="Y",R39="Y",S39="N",T39="Y",U39="Y"),"Detect with IS Supp","ND")) -> #DIV/0! | Q39: =IF(AND(D39<($D$32+0.1),D39>($D$32-0.1)),"Y","N") -> Y | R39: =IF(E39>$E$34,"Y","N") -> N | S39: =IF(M39>$M$34,"Y","N") -> N | T39: =IF(H39>$H$34,"Y","N") -> N | U39: =IF(AND(J39>=$J$34, J39<=$K$34), "Y","N") -> #DIV/0! | V39: =IF(AND(Q39="Y",R39="Y",S39="Y",T39="Y",U39="Y"), "PASS","FAIL") -> #DIV/0!
O40: =IF(V40="PASS","DETECT",IF(AND(Q40="Y",R40="Y",S40="N",T40="Y",U40="Y"),"Detect with IS Supp","ND")) -> #DIV/0! | Q40: =IF(AND(D40<($D$32+0.1),D40>($D$32-0.1)),"Y","N") -> Y | R40: =IF(E40>$E$34,"Y","N") -> N | S40: =IF(M40>$M$34,"Y","N") -> N | T40: =IF(H40>$H$34,"Y","N") -> N | U40: =IF(AND(J40>=$J$34, J40<=$K$34), "Y","N") -> #DIV/0! | V40: =IF(AND(Q40="Y",R40="Y",S40="Y",T40="Y",U40="Y"), "PASS","FAIL") -> #DIV/0!
O41: =IF(V41="PASS","DETECT",IF(AND(Q41="Y",R41="Y",S41="N",T41="Y",U41="Y"),"Detect with IS Supp","ND")) -> #DIV/0! | Q41: =IF(AND(D41<($D$32+0.1),D41>($D$32-0.1)),"Y","N") -> Y | R41: =IF(E41>$E$34,"Y","N") -> N | S41: =IF(M41>$M$34,"Y","N") -> N | T41: =IF(H41>$H$34,"Y","N") -> N | U41: =IF(AND(J41>=$J$34, J41<=$K$34), "Y","N") -> #DIV/0! | V41: =IF(AND(Q41="Y",R41="Y",S41="Y",T41="Y",U41="Y"), "PASS","FAIL") -> #DIV/0!
O42: =IF(V42="PASS","DETECT",IF(AND(Q42="Y",R42="Y",S42="N",T42="Y",U42="Y"),"Detect with IS Supp","ND")) -> #DIV/0! | Q42: =IF(AND(D42<($D$32+0.1),D42>($D$32-0.1)),"Y","N") -> Y | R42: =IF(E42>$E$34,"Y","N") -> N | S42: =IF(M42>$M$34,"Y","N") -> N | T42: =IF(H42>$H$34,"Y","N") -> N | U42: =IF(AND(J42>=$J$34, J42<=$K$34), "Y","N") -> #DIV/0! | V42: =IF(AND(Q42="Y",R42="Y",S42="Y",T42="Y",U42="Y"), "PASS","FAIL") -> #DIV/0!
O43: =IF(V43="PASS","DETECT",IF(AND(Q43="Y",R43="Y",S43="N",T43="Y",U43="Y"),"Detect with IS Supp","ND")) -> #DIV/0! | Q43: =IF(AND(D43<($D$32+0.1),D43>($D$32-0.1)),"Y","N") -> Y | R43: =IF(E43>$E$34,"Y","N") -> N | S43: =IF(M43>$M$34,"Y","N") -> N | T43: =IF(H43>$H$34,"Y","N") -> N | U43: =IF(AND(J43>=$J$34, J43<=$K$34), "Y","N") -> #DIV/0! | V43: =IF(AND(Q43="Y",R43="Y",S43="Y",T43="Y",U43="Y"), "PASS","FAIL") -> #DIV/0!
O44: =IF(V44="PASS","DETECT",IF(AND(Q44="Y",R44="Y",S44="N",T44="Y",U44="Y"),"Detect with IS Supp","ND")) -> #DIV/0! | Q44: =IF(AND(D44<($D$32+0.1),D44>($D$32-0.1)),"Y","N") -> Y | R44: =IF(E44>$E$34,"Y","N") -> N | S44: =IF(M44>$M$34,"Y","N") -> N | T44: =IF(H44>$H$34,"Y","N") -> N | U44: =IF(AND(J44>=$J$34, J44<=$K$34), "Y","N") -> #DIV/0! | V44: =IF(AND(Q44="Y",R44="Y",S44="Y",T44="Y",U44="Y"), "PASS","FAIL") -> #DIV/0!
O45: =IF(V45="PASS","DETECT",IF(AND(Q45="Y",R45="Y",S45="N",T45="Y",U45="Y"),"Detect with IS Supp","ND")) -> #DIV/0! | Q45: =IF(AND(D45<($D$32+0.1),D45>($D$32-0.1)),"Y","N") -> Y | R45: =IF(E45>$E$34,"Y","N") -> N | S45: =IF(M45>$M$34,"Y","N") -> N | T45: =IF(H45>$H$34,"Y","N") -> N | U45: =IF(AND(J45>=$J$34, J45<=$K$34), "Y","N") -> #DIV/0! | V45: =IF(AND(Q45="Y",R45="Y",S45="Y",T45="Y",U45="Y"), "PASS","FAIL") -> #DIV/0!
O46: =IF(V46="PASS","DETECT",IF(AND(Q46="Y",R46="Y",S46="N",T46="Y",U46="Y"),"Detect with IS Supp","ND")) -> #DIV/0! | Q46: =IF(AND(D46<($D$32+0.1),D46>($D$32-0.1)),"Y","N") -> Y | R46: =IF(E46>$E$34,"Y","N") -> N | S46: =IF(M46>$M$34,"Y","N") -> N | T46: =IF(H46>$H$34,"Y","N") -> N | U46: =IF(AND(J46>=$J$34, J46<=$K$34), "Y","N") -> #DIV/0! | V46: =IF(AND(Q46="Y",R46="Y",S46="Y",T46="Y",U46="Y"), "PASS","FAIL") -> #DIV/0!
O47: =IF(V47="PASS","DETECT",IF(AND(Q47="Y",R47="Y",S47="N",T47="Y",U47="Y"),"Detect with IS Supp","ND")) -> #DIV/0! | Q47: =IF(AND(D47<($D$32+0.1),D47>($D$32-0.1)),"Y","N") -> Y | R47: =IF(E47>$E$34,"Y","N") -> N | S47: =IF(M47>$M$34,"Y","N") -> N | T47: =IF(H47>$H$34,"Y","N") -> N | U47: =IF(AND(J47>=$J$34, J47<=$K$34), "Y","N") -> #DIV/0! | V47: =IF(AND(Q47="Y",R47="Y",S47="Y",T47="Y",U47="Y"), "PASS","FAIL") -> #DIV/0!
O48: =IF(V48="PASS","DETECT",IF(AND(Q48="Y",R48="Y",S48="N",T48="Y",U48="Y"),"Detect with IS Supp","ND")) -> #DIV/0! | Q48: =IF(AND(D48<($D$32+0.1),D48>($D$32-0.1)),"Y","N") -> Y | R48: =IF(E48>$E$34,"Y","N") -> N | S48: =IF(M48>$M$34,"Y","N") -> N | T48: =IF(H48>$H$34,"Y","N") -> N | U48: =IF(AND(J48>=$J$34, J48<=$K$34), "Y","N") -> #DIV/0! | V48: =IF(AND(Q48="Y",R48="Y",S48="Y",T48="Y",U48="Y"), "PASS","FAIL") -> #DIV/0!
...

Sheet Xylazine
A1: Xylazine
A4: =Codeine!A4 -> Method/SOP | D4: =Codeine!D4 -> Column Lot #: | H4: =Codeine!H4 -> Urine Lot #: | J4: =Codeine!J4 -> Standards Date:
A5: =Codeine!A5 -> Batch ID: | D5: =Codeine!D5 -> Instrument: | H5: =Codeine!H5 -> Analyst: | J5: =Codeine!J5 -> Reviewer:
A7: QC Criteria
A8: Paste LRL and QCH Results in the light blue shaded areas. Paste LRL results in row 17 and QCH results in row 18.
A10: QC Low (LRL) | B10: Response | F10: Retention Time | I10: QC High | J10: Response | N10: Retention Time
B11: 25% of Lowest | D11: Run Value | E11: Pass/Fail | F11: Characterization | H11: Run Value | J11: 25% of Lowest | L11: Run Value | M11: Pass/Fail | N11: Characterization | P11: Run Value
B12: Analytical | C12: 9449.9969 | D12: =E24 -> 0 | E12: =IF(D12>C12,"PASS","FAIL") -> FAIL | F12: Avg | G12: =$D$24 -> 0 | H12: =D24 -> 0 | J12: Analytical | K12: 223870.58 | L12: =E25 -> 0 | M12: =IF(L12>K12,"PASS","FAIL") -> FAIL | N12: Avg | O12: =$D$24 -> 0 | P12: =D25 -> 0
B13: Qualifier | C13: 7.6286251 | D13: =J24 -> 0 | E13: =IF(D13>C13,"PASS","FAIL") -> FAIL | F13: 0.1 | G13: =G12+0.1 -> 0.1 | H13: Pass/Fail | J13: Qualifier | K13: 7.5762181 | L13: =J25 -> 0 | M13: =IF(L13>K13,"PASS","FAIL") -> FAIL | N13: 0.1 | O13: =O12+0.1 -> 0.1 | P13: Pass/Fail
B14: IS | C14: 13851.425 | D14: =M24 -> 0 | E14: =IF(D14>C14,"PASS","FAIL") -> FAIL | F14: -0.1 | G14: =G12-0.1 -> -0.1 | H14: =IF(AND(H12>G14,H12<G13),"PASS","FAIL") -> PASS | J14: IS | K14: 15109.057 | L14: =M25 -> 0 | M14: =IF(L14>K14,"PASS","FAIL") -> FAIL | N14: -0.1 | O14: =O12-0.1 -> -0.1 | P14: =IF(AND(P12>O14,P12<O13),"PASS","FAIL") -> PASS
A16: QC Low (LRL) | B16: Response | F16: Retention Time | I16: QC High | J16: Response | N16: Retention Time
B17: 25% of Lowest | D17: Run Value | E17: Pass/Fail | F17: Characterization | H17: Run Value | J17: 25% of Lowest | L17: Run Value | M17: Pass/Fail | N17: Characterization | P17: Run Value
B18: Analytical | C18: 9449.9969 | D18: =E26 -> 0 | E18: =IF(D18>C18,"PASS","FAIL") -> FAIL | F18: Avg | G18: =$D$24 -> 0 | H18: =D26 -> 0 | J18: Analytical | K18: 223870.58 | L18: =E27 -> 0 | M18: =IF(L18>K18,"PASS","FAIL") -> FAIL | N18: Avg | O18: =$D$24 -> 0 | P18: =D27 -> 0
B19: Qualifier | C19: 7.6286251 | D19: =J26 -> 0 | E19: =IF(D19>C19,"PASS","FAIL") -> FAIL | F19: 0.1 | G19: =G18+0.1 -> 0.1 | H19: Pass/Fail | J19: Qualifier | K19: 7.5762181 | L19: =J27 -> 0 | M19: =IF(L19>K19,"PASS","FAIL") -> FAIL | N19: 0.1 | O19: =O18+0.1 -> 0.1 | P19: Pass/Fail
B20: IS | C20: 13851.425 | D20: =M26 -> 0 | E20: =IF(D20>C20,"PASS","FAIL") -> FAIL | F20: -0.1 | G20: =G18-0.1 -> -0.1 | H20: =IF(AND(H18>G20,H18<G19),"PASS","FAIL") -> PASS | J20: IS | K20: 15109.057 | L20: =M27 -> 0 | M20: =IF(L20>K20,"PASS","FAIL") -> FAIL | N20: -0.1 | O20: =O18-0.1 -> -0.1 | P20: =IF(AND(P18>O20,P18<O19),"PASS","FAIL") -> PASS
A22: Sample | D22: =D60 -> Xylazine Results | I22: =I60 -> Qualifier (221.1 -> 72.0) Method | J22: =J60 -> Qualifier (221.1 -> 72.0) Results | L22: =L60 -> Xylazine D6 (ISTD) Results
A23: Name | B23: Data File | C23: Acq. Date-Time | D23: RT | E23: Resp. | F23: MI | G23: S/N | H23: RR | I23: Rel. Resp. | J23: Ratio | K23: MI | L23: RT | M23: Resp. | N23: S/N
A24: Opening QCL
A25: Opening QCH
A26: Closing QCL
A27: Closing QCH
A29: Sample Criteria | Q29: Sample Criteria QC
A30: Paste Sample Results in the light orange shaded areas.If more than 10 samples were analyzed in the bracket, add rows and drag down formulas. Conditional formatting will highlight RED if the sample fails for the criteria and GREEN if it passes for the criteria. All criteria must be GREEN for a sample to be considered a DETECT.
A31: 20 Samples between QCs? | B31: Yes | C31: 1. Retention Time | E31: 2. Analyte Response | H31: 3. Resp. Ratio | I31: 4. Qualifier | M31: 5. ISTD | O31: Sample Result
C32: Avg In-Run RT | D32: =$D$24 -> 0 | E32: In-Run QCL Response Threshold | H32: In-Run QCL RR | J32: Qualifier Ion Ratio Limits | M32: Response Threshold
C33: RT Limits | D33: =D32-0.1 -> -0.1
D34: =(D32+0.1) -> 0.1 | E34: =E24 -> 0 | H34: =H24 -> 0 | J34: =AVERAGE(J24,J25)*0.8 -> #DIV/0! | K34: =AVERAGE(J24,J25)*1.2 -> #DIV/0! | M34: =C14 -> 13851.425
A36: Sample | D36: =D22 -> Xylazine Results | I36: =I22 -> Qualifier (221.1 -> 72.0) Method | J36: =J22 -> Qualifier (221.1 -> 72.0) Results | L36: =L22 -> Xylazine D6 (ISTD) Results
A37: Name | B37: Data File | C37: Acq. Date-Time | D37: RT | E37: Resp. | F37: MI | G37: S/N | H37: RR | I37: Rel. Resp. From LRL | J37: Ratio | K37: MI | L37: RT | M37: Resp. | N37: S/N | O37: Detect/ND | Q37: RT PASS? | R37: ANALYTE RESP. PASS? | S37: IS PASS? | T37: RR PASS? | U37: Qual Ion Ratio <0 | V37: All criteria met?
O38: =IF(V38="PASS","DETECT",IF(AND(Q38="Y",R38="Y",S38="N",T38="Y",U38="Y"),"Detect with IS Supp","ND")) -> #DIV/0! | Q38: =IF(AND(D38<($D$32+0.1),D38>($D$32-0.1)),"Y","N") -> Y | R38: =IF(E38>$E$34,"Y","N") -> N | S38: =IF(M38>$M$34,"Y","N") -> N | T38: =IF(H38>$H$34,"Y","N") -> N | U38: =IF(AND(J38>=$J$34, J38<=$K$34), "Y","N") -> #DIV/0! | V38: =IF(AND(Q38="Y",R38="Y",S38="Y",T38="Y",U38="Y"), "PASS","FAIL") -> #DIV/0!
O39: =IF(V39="PASS","DETECT",IF(AND(Q39="Y",R39="Y",S39="N",T39="Y",U39="Y"),"Detect with IS Supp","ND")) -> #DIV/0! | Q39: =IF(AND(D39<($D$32+0.1),D39>($D$32-0.1)),"Y","N") -> Y | R39: =IF(E39>$E$34,"Y","N") -> N | S39: =IF(M39>$M$34,"Y","N") -> N | T39: =IF(H39>$H$34,"Y","N") -> N | U39: =IF(AND(J39>=$J$34, J39<=$K$34), "Y","N") -> #DIV/0! | V39: =IF(AND(Q39="Y",R39="Y",S39="Y",T39="Y",U39="Y"), "PASS","FAIL") -> #DIV/0!
O40: =IF(V40="PASS","DETECT",IF(AND(Q40="Y",R40="Y",S40="N",T40="Y",U40="Y"),"Detect with IS Supp","ND")) -> #DIV/0! | Q40: =IF(AND(D40<($D$32+0.1),D40>($D$32-0.1)),"Y","N") -> Y | R40: =IF(E40>$E$34,"Y","N") -> N | S40: =IF(M40>$M$34,"Y","N") -> N | T40: =IF(H40>$H$34,"Y","N") -> N | U40: =IF(AND(J40>=$J$34, J40<=$K$34), "Y","N") -> #DIV/0! | V40: =IF(AND(Q40="Y",R40="Y",S40="Y",T40="Y",U40="Y"), "PASS","FAIL") -> #DIV/0!
O41: =IF(V41="PASS","DETECT",IF(AND(Q41="Y",R41="Y",S41="N",T41="Y",U41="Y"),"Detect with IS Supp","ND")) -> #DIV/0! | Q41: =IF(AND(D41<($D$32+0.1),D41>($D$32-0.1)),"Y","N") -> Y | R41: =IF(E41>$E$34,"Y","N") -> N | S41: =IF(M41>$M$34,"Y","N") -> N | T41: =IF(H41>$H$34,"Y","N") -> N | U41: =IF(AND(J41>=$J$34, J41<=$K$34), "Y","N") -> #DIV/0! | V41: =IF(AND(Q41="Y",R41="Y",S41="Y",T41="Y",U41="Y"), "PASS","FAIL") -> #DIV/0!
O42: =IF(V42="PASS","DETECT",IF(AND(Q42="Y",R42="Y",S42="N",T42="Y",U42="Y"),"Detect with IS Supp","ND")) -> #DIV/0! | Q42: =IF(AND(D42<($D$32+0.1),D42>($D$32-0.1)),"Y","N") -> Y | R42: =IF(E42>$E$34,"Y","N") -> N | S42: =IF(M42>$M$34,"Y","N") -> N | T42: =IF(H42>$H$34,"Y","N") -> N | U42: =IF(AND(J42>=$J$34, J42<=$K$34), "Y","N") -> #DIV/0! | V42: =IF(AND(Q42="Y",R42="Y",S42="Y",T42="Y",U42="Y"), "PASS","FAIL") -> #DIV/0!
O43: =IF(V43="PASS","DETECT",IF(AND(Q43="Y",R43="Y",S43="N",T43="Y",U43="Y"),"Detect with IS Supp","ND")) -> #DIV/0! | Q43: =IF(AND(D43<($D$32+0.1),D43>($D$32-0.1)),"Y","N") -> Y | R43: =IF(E43>$E$34,"Y","N") -> N | S43: =IF(M43>$M$34,"Y","N") -> N | T43: =IF(H43>$H$34,"Y","N") -> N | U43: =IF(AND(J43>=$J$34, J43<=$K$34), "Y","N") -> #DIV/0! | V43: =IF(AND(Q43="Y",R43="Y",S43="Y",T43="Y",U43="Y"), "PASS","FAIL") -> #DIV/0!
O44: =IF(V44="PASS","DETECT",IF(AND(Q44="Y",R44="Y",S44="N",T44="Y",U44="Y"),"Detect with IS Supp","ND")) -> #DIV/0! | Q44: =IF(AND(D44<($D$32+0.1),D44>($D$32-0.1)),"Y","N") -> Y | R44: =IF(E44>$E$34,"Y","N") -> N | S44: =IF(M44>$M$34,"Y","N") -> N | T44: =IF(H44>$H$34,"Y","N") -> N | U44: =IF(AND(J44>=$J$34, J44<=$K$34), "Y","N") -> #DIV/0! | V44: =IF(AND(Q44="Y",R44="Y",S44="Y",T44="Y",U44="Y"), "PASS","FAIL") -> #DIV/0!
O45: =IF(V45="PASS","DETECT",IF(AND(Q45="Y",R45="Y",S45="N",T45="Y",U45="Y"),"Detect with IS Supp","ND")) -> #DIV/0! | Q45: =IF(AND(D45<($D$32+0.1),D45>($D$32-0.1)),"Y","N") -> Y | R45: =IF(E45>$E$34,"Y","N") -> N | S45: =IF(M45>$M$34,"Y","N") -> N | T45: =IF(H45>$H$34,"Y","N") -> N | U45: =IF(AND(J45>=$J$34, J45<=$K$34), "Y","N") -> #DIV/0! | V45: =IF(AND(Q45="Y",R45="Y",S45="Y",T45="Y",U45="Y"), "PASS","FAIL") -> #DIV/0!
O46: =IF(V46="PASS","DETECT",IF(AND(Q46="Y",R46="Y",S46="N",T46="Y",U46="Y"),"Detect with IS Supp","ND")) -> #DIV/0! | Q46: =IF(AND(D46<($D$32+0.1),D46>($D$32-0.1)),"Y","N") -> Y | R46: =IF(E46>$E$34,"Y","N") -> N | S46: =IF(M46>$M$34,"Y","N") -> N | T46: =IF(H46>$H$34,"Y","N") -> N | U46: =IF(AND(J46>=$J$34, J46<=$K$34), "Y","N") -> #DIV/0! | V46: =IF(AND(Q46="Y",R46="Y",S46="Y",T46="Y",U46="Y"), "PASS","FAIL") -> #DIV/0!
O47: =IF(V47="PASS","DETECT",IF(AND(Q47="Y",R47="Y",S47="N",T47="Y",U47="Y"),"Detect with IS Supp","ND")) -> #DIV/0! | Q47: =IF(AND(D47<($D$32+0.1),D47>($D$32-0.1)),"Y","N") -> Y | R47: =IF(E47>$E$34,"Y","N") -> N | S47: =IF(M47>$M$34,"Y","N") -> N | T47: =IF(H47>$H$34,"Y","N") -> N | U47: =IF(AND(J47>=$J$34, J47<=$K$34), "Y","N") -> #DIV/0! | V47: =IF(AND(Q47="Y",R47="Y",S47="Y",T47="Y",U47="Y"), "PASS","FAIL") -> #DIV/0!
O48: =IF(V48="PASS","DETECT",IF(AND(Q48="Y",R48="Y",S48="N",T48="Y",U48="Y"),"Detect with IS Supp","ND")) -> #DIV/0! | Q48: =IF(AND(D48<($D$32+0.1),D48>($D$32-0.1)),"Y","N") -> Y | R48: =IF(E48>$E$34,"Y","N") -> N | S48: =IF(M48>$M$34,"Y","N") -> N | T48: =IF(H48>$H$34,"Y","N") -> N | U48: =IF(AND(J48>=$J$34, J48<=$K$34), "Y","N") -> #DIV/0! | V48: =IF(AND(Q48="Y",R48="Y",S48="Y",T48="Y",U48="Y"), "PASS","FAIL") -> #DIV/0!
...

Sheet Heroin
A1: Heroin
A4: =Codeine!A4 -> Method/SOP | D4: =Codeine!D4 -> Column Lot #: | H4: =Codeine!H4 -> Urine Lot #: | J4: =Codeine!J4 -> Standards Date:
A5: =Codeine!A5 -> Batch ID: | D5: =Codeine!D5 -> Instrument: | H5: =Codeine!H5 -> Analyst: | J5: =Codeine!J5 -> Reviewer:
A7: QC Criteria
A8: Paste LRL and QCH Results in the light blue shaded areas. Paste LRL results in row 17 and QCH results in row 18.
A10: QC Low (LRL) | B10: Response | F10: Retention Time | I10: QC High | J10: Response | N10: Retention Time
B11: 25% of Lowest | D11: Run Value | E11: Pass/Fail | F11: Characterization | H11: Run Value | J11: 25% of Lowest | L11: Run Value | M11: Pass/Fail | N11: Characterization | P11: Run Value
B12: Analytical | C12: 410.03382 | D12: =E24 -> 0 | E12: =IF(D12>C12,"PASS","FAIL") -> FAIL | F12: Avg | G12: =$D$24 -> 0 | H12: =D24 -> 0 | J12: Analytical | K12: 12568.56 | L12: =E25 -> 0 | M12: =IF(L12>K12,"PASS","FAIL") -> FAIL | N12: Avg | O12: =$D$24 -> 0 | P12: =D25 -> 0
B13: Qualifier | C13: 17.025968 | D13: =J24 -> 0 | E13: =IF(D13>C13,"PASS","FAIL") -> FAIL | F13: 0.1 | G13: =G12+0.1 -> 0.1 | H13: Pass/Fail | J13: Qualifier | K13: 19.203995 | L13: =J25 -> 0 | M13: =IF(L13>K13,"PASS","FAIL") -> FAIL | N13: 0.1 | O13: =O12+0.1 -> 0.1 | P13: Pass/Fail
B14: IS | C14: 864.10497 | D14: =M24 -> 0 | E14: =IF(D14>C14,"PASS","FAIL") -> FAIL | F14: -0.1 | G14: =G12-0.1 -> -0.1 | H14: =IF(AND(H12>G14,H12<G13),"PASS","FAIL") -> PASS | J14: IS | K14: 1056.0128 | L14: =M25 -> 0 | M14: =IF(L14>K14,"PASS","FAIL") -> FAIL | N14: -0.1 | O14: =O12-0.1 -> -0.1 | P14: =IF(AND(P12>O14,P12<O13),"PASS","FAIL") -> PASS
A16: QC Low (LRL) | B16: Response | F16: Retention Time | I16: QC High | J16: Response | N16: Retention Time
B17: 25% of Lowest | D17: Run Value | E17: Pass/Fail | F17: Characterization | H17: Run Value | J17: 25% of Lowest | L17: Run Value | M17: Pass/Fail | N17: Characterization | P17: Run Value
B18: Analytical | C18: 410.03382 | D18: =E26 -> 0 | E18: =IF(D18>C18,"PASS","FAIL") -> FAIL | F18: Avg | G18: =$D$24 -> 0 | H18: =D26 -> 0 | J18: Analytical | K18: 12568.56 | L18: =E27 -> 0 | M18: =IF(L18>K18,"PASS","FAIL") -> FAIL | N18: Avg | O18: =$D$24 -> 0 | P18: =D27 -> 0
B19: Qualifier | C19: 17.025968 | D19: =J26 -> 0 | E19: =IF(D19>C19,"PASS","FAIL") -> FAIL | F19: 0.1 | G19: =G18+0.1 -> 0.1 | H19: Pass/Fail | J19: Qualifier | K19: 19.203995 | L19: =J27 -> 0 | M19: =IF(L19>K19,"PASS","FAIL") -> FAIL | N19: 0.1 | O19: =O18+0.1 -> 0.1 | P19: Pass/Fail
B20: IS | C20: 864.10497 | D20: =M26 -> 0 | E20: =IF(D20>C20,"PASS","FAIL") -> FAIL | F20: -0.1 | G20: =G18-0.1 -> -0.1 | H20: =IF(AND(H18>G20,H18<G19),"PASS","FAIL") -> PASS | J20: IS | K20: 1056.0128 | L20: =M27 -> 0 | M20: =IF(L20>K20,"PASS","FAIL") -> FAIL | N20: -0.1 | O20: =O18-0.1 -> -0.1 | P20: =IF(AND(P18>O20,P18<O19),"PASS","FAIL") -> PASS
A22: Sample | D22: =D60 -> Heroin Results | I22: =I60 -> Qualifier (370.2 -> 211.0) Method | J22: =J60 -> Qualifier (370.2 -> 211.0) Results | L22: =L60 -> Heroin D3 (ISTD) Results
A23: Name | B23: Data File | C23: Acq. Date-Time | D23: RT | E23: Resp. | F23: MI | G23: S/N | H23: RR | I23: Rel. Resp. | J23: Ratio | K23: MI | L23: RT | M23: Resp. | N23: S/N
A24: Opening QCL
A25: Opening QCH
A26: Closing QCL
A27: Closing QCH
A29: Sample Criteria | Q29: Sample Criteria QC
A30: Paste Sample Results in the light orange shaded areas.If more than 10 samples were analyzed in the bracket, add rows and drag down formulas. Conditional formatting will highlight RED if the sample fails for the criteria and GREEN if it passes for the criteria. All criteria must be GREEN for a sample to be considered a DETECT.
A31: 20 Samples between QCs? | B31: Yes | C31: 1. Retention Time | E31: 2. Analyte Response | H31: 3. Resp. Ratio | I31: 4. Qualifier | M31: 5. ISTD | O31: Sample Result
C32: Avg In-Run RT | D32: =$D$24 -> 0 | E32: In-Run QCL Response Threshold | H32: In-Run QCL RR | J32: Qualifier Ion Ratio Limits | M32: Response Threshold
C33: RT Limits | D33: =D32-0.1 -> -0.1
D34: =(D32+0.1) -> 0.1 | E34: =E24 -> 0 | H34: =H24 -> 0 | J34: =AVERAGE(J24,J25)*0.8 -> #DIV/0! | K34: =AVERAGE(J24,J25)*1.2 -> #DIV/0! | M34: =C14 -> 864.10497
A36: Sample | D36: =D22 -> Heroin Results | I36: =I22 -> Qualifier (370.2 -> 211.0) Method | J36: =J22 -> Qualifier (370.2 -> 211.0) Results | L36: =L22 -> Heroin D3 (ISTD) Results
A37: Name | B37: Data File | C37: Acq. Date-Time | D37: RT | E37: Resp. | F37: MI | G37: S/N | H37: RR | I37: Rel. Resp. From LRL | J37: Ratio | K37: MI | L37: RT | M37: Resp. | N37: S/N | O37: Detect/ND | Q37: RT PASS? | R37: ANALYTE RESP. PASS? | S37: IS PASS? | T37: RR PASS? | U37: Qual Ion Ratio <0 | V37: All criteria met?
O38: =IF(V38="PASS","DETECT",IF(AND(Q38="Y",R38="Y",S38="N",T38="Y",U38="Y"),"Detect with IS Supp","ND")) -> #DIV/0! | Q38: =IF(AND(D38<($D$32+0.1),D38>($D$32-0.1)),"Y","N") -> Y | R38: =IF(E38>$E$34,"Y","N") -> N | S38: =IF(M38>$M$34,"Y","N") -> N | T38: =IF(H38>$H$34,"Y","N") -> N | U38: =IF(AND(J38>=$J$34, J38<=$K$34), "Y","N") -> #DIV/0! | V38: =IF(AND(Q38="Y",R38="Y",S38="Y",T38="Y",U38="Y"), "PASS","FAIL") -> #DIV/0!
O39: =IF(V39="PASS","DETECT",IF(AND(Q39="Y",R39="Y",S39="N",T39="Y",U39="Y"),"Detect with IS Supp","ND")) -> #DIV/0! | Q39: =IF(AND(D39<($D$32+0.1),D39>($D$32-0.1)),"Y","N") -> Y | R39: =IF(E39>$E$34,"Y","N") -> N | S39: =IF(M39>$M$34,"Y","N") -> N | T39: =IF(H39>$H$34,"Y","N") -> N | U39: =IF(AND(J39>=$J$34, J39<=$K$34), "Y","N") -> #DIV/0! | V39: =IF(AND(Q39="Y",R39="Y",S39="Y",T39="Y",U39="Y"), "PASS","FAIL") -> #DIV/0!
