Workbook

Sheet Westgard Rules
A1: QC Data from Raw | F1: General Statistics | K1: 13s Rule | P1: 10x Rule
A2: Date & Time | B2: QCL | C2: QCM | D2: QCH | G2: QCL | H2: QCM | I2: QCH | L2: QCL | M2: QCM | N2: QCH | Q2: QCL | R2: QCM | S2: QCH
A3: ='RAW DATA'!J2 -> 0 | B3: ='RAW DATA'!L2 -> 0 | C3: ='RAW DATA'!L22 -> 0 | D3: ='RAW DATA'!L42 -> 0 | F3: Mean | G3: =AVERAGE(B3:B22) -> 0 | H3: =AVERAGE(C3:C22) -> 0 | I3: =AVERAGE(D3:D22) -> 0 | K3: =A3 -> 0 | L3: =IF(OR(ABS(B3-$G$3)>3*$G$4),"FAIL","PASS") -> PASS | M3: =IF(OR(ABS(C3-$H$3)>3*$H$4),"FAIL","PASS") -> PASS | N3: =IF(OR(ABS(D3-$I$3)>3*$I$4),"FAIL","PASS") -> PASS | P3: First Half | Q3: {=IF(OR( ABS(SUMPRODUCT(SIGN(B3:B12-$G$3)))=10, ),"FAIL","PASS")} -> PASS | R3: {=IF(OR( ABS(SUMPRODUCT(SIGN(C3:C12-$H$3)))=10, ),"FAIL","PASS")} -> PASS | S3: {=IF(OR( ABS(SUMPRODUCT(SIGN(D3:D12-$I$3)))=10, ),"FAIL","PASS")} -> PASS
A4: ='RAW DATA'!J3 -> 0 | B4: ='RAW DATA'!L3 -> 0 | C4: ='RAW DATA'!L23 -> 0 | D4: ='RAW DATA'!L43 -> 0 | F4: SD | G4: =_xlfn.STDEV.P(B3:B22) -> 0 | H4: =_xlfn.STDEV.P(C3:C22) -> 0 | I4: =_xlfn.STDEV.P(D3:D22) -> 0 | K4: =A4 -> 0 | L4: =IF(OR(ABS(B4-$G$3)>3*$G$4),"FAIL","PASS") -> PASS | M4: =IF(OR(ABS(C4-$H$3)>3*$H$4),"FAIL","PASS") -> PASS | N4: =IF(OR(ABS(D4-$I$3)>3*$I$4),"FAIL","PASS") -> PASS | P4: Second Half | Q4: {=IF(OR( ABS(SUMPRODUCT(SIGN(B4:B13-$G$3)))=10, ),"FAIL","PASS")} -> PASS | R4: {=IF(OR( ABS(SUMPRODUCT(SIGN(C4:C13-$H$3)))=10, ),"FAIL","PASS")} -> PASS | S4: {=IF(OR( ABS(SUMPRODUCT(SIGN(D4:D13-$I$3)))=10, ),"FAIL","PASS")} -> PASS
A5: ='RAW DATA'!J4 -> 0 | B5: ='RAW DATA'!L4 -> 0 | C5: ='RAW DATA'!L24 -> 0 | D5: ='RAW DATA'!L44 -> 0 | K5: =A5 -> 0 | L5: =IF(OR(ABS(B5-$G$3)>3*$G$4),"FAIL","PASS") -> PASS | M5: =IF(OR(ABS(C5-$H$3)>3*$H$4),"FAIL","PASS") -> PASS | N5: =IF(OR(ABS(D5-$I$3)>3*$I$4),"FAIL","PASS") -> PASS
A6: ='RAW DATA'!J5 -> 0 | B6: ='RAW DATA'!L5 -> 0 | C6: ='RAW DATA'!L25 -> 0 | D6: ='RAW DATA'!L45 -> 0 | F6: 2σ | G6: =G4*2 -> 0 | H6: =H4*2 -> 0 | I6: =I4*2 -> 0 | K6: =A6 -> 0 | L6: =IF(OR(ABS(B6-$G$3)>3*$G$4),"FAIL","PASS") -> PASS | M6: =IF(OR(ABS(C6-$H$3)>3*$H$4),"FAIL","PASS") -> PASS | N6: =IF(OR(ABS(D6-$I$3)>3*$I$4),"FAIL","PASS") -> PASS | P6: R4s Rule
A7: ='RAW DATA'!J6 -> 0 | B7: ='RAW DATA'!L6 -> 0 | C7: ='RAW DATA'!L26 -> 0 | D7: ='RAW DATA'!L46 -> 0 | F7: 3σ | G7: =G4*3 -> 0 | H7: =H4*3 -> 0 | I7: =I4*3 -> 0 | K7: =A7 -> 0 | L7: =IF(OR(ABS(B7-$G$3)>3*$G$4),"FAIL","PASS") -> PASS | M7: =IF(OR(ABS(C7-$H$3)>3*$H$4),"FAIL","PASS") -> PASS | N7: =IF(OR(ABS(D7-$I$3)>3*$I$4),"FAIL","PASS") -> PASS | Q7: QCL | R7: QCM | S7: QCH
A8: ='RAW DATA'!J7 -> 0 | B8: ='RAW DATA'!L7 -> 0 | C8: ='RAW DATA'!L27 -> 0 | D8: ='RAW DATA'!L47 -> 0 | K8: =A8 -> 0 | L8: =IF(OR(ABS(B8-$G$3)>3*$G$4),"FAIL","PASS") -> PASS | M8: =IF(OR(ABS(C8-$H$3)>3*$H$4),"FAIL","PASS") -> PASS | N8: =IF(OR(ABS(D8-$I$3)>3*$I$4),"FAIL","PASS") -> PASS | P8: =A3 -> 0 | Q8: =IF(OR( ABS(B4-B3)>=4*$G$3, ),"FAIL","PASS") -> FAIL | R8: =IF(OR( ABS(C4-C3)>=4*$H$3, ),"FAIL","PASS") -> FAIL | S8: =IF(OR( ABS(D4-D3)>=4*$I$3, ),"FAIL","PASS") -> FAIL
A9: ='RAW DATA'!J8 -> 0 | B9: ='RAW DATA'!L8 -> 0 | C9: ='RAW DATA'!L28 -> 0 | D9: ='RAW DATA'!L48 -> 0 | F9: Plus 2σ | G9: =G3+G6 -> 0 | H9: =H3+H6 -> 0 | I9: =I3+I6 -> 0 | K9: =A9 -> 0 | L9: =IF(OR(ABS(B9-$G$3)>3*$G$4),"FAIL","PASS") -> PASS | M9: =IF(OR(ABS(C9-$H$3)>3*$H$4),"FAIL","PASS") -> PASS | N9: =IF(OR(ABS(D9-$I$3)>3*$I$4),"FAIL","PASS") -> PASS | P9: =A4 -> 0 | Q9: =IF(OR( ABS(B5-B4)>=4*$G$3, ),"FAIL","PASS") -> FAIL | R9: =IF(OR( ABS(C5-C4)>=4*$H$3, ),"FAIL","PASS") -> FAIL | S9: =IF(OR( ABS(D5-D4)>=4*$I$3, ),"FAIL","PASS") -> FAIL
A10: ='RAW DATA'!J9 -> 0 | B10: ='RAW DATA'!L9 -> 0 | C10: ='RAW DATA'!L29 -> 0 | D10: ='RAW DATA'!L49 -> 0 | F10: Plus 3σ | G10: =G3+G7 -> 0 | H10: =H3+H7 -> 0 | I10: =I3+I7 -> 0 | K10: =A10 -> 0 | L10: =IF(OR(ABS(B10-$G$3)>3*$G$4),"FAIL","PASS") -> PASS | M10: =IF(OR(ABS(C10-$H$3)>3*$H$4),"FAIL","PASS") -> PASS | N10: =IF(OR(ABS(D10-$I$3)>3*$I$4),"FAIL","PASS") -> PASS | P10: =A5 -> 0 | Q10: =IF(OR( ABS(B6-B5)>=4*$G$3, ),"FAIL","PASS") -> FAIL | R10: =IF(OR( ABS(C6-C5)>=4*$H$3, ),"FAIL","PASS") -> FAIL | S10: =IF(OR( ABS(D6-D5)>=4*$I$3, ),"FAIL","PASS") -> FAIL
A11: ='RAW DATA'!J10 -> 0 | B11: ='RAW DATA'!L10 -> 0 | C11: ='RAW DATA'!L30 -> 0 | D11: ='RAW DATA'!L50 -> 0 | F11: Minus 2σ | G11: =G3-G6 -> 0 | H11: =H3-H6 -> 0 | I11: =I3-I6 -> 0 | K11: =A11 -> 0 | L11: =IF(OR(ABS(B11-$G$3)>3*$G$4),"FAIL","PASS") -> PASS | M11: =IF(OR(ABS(C11-$H$3)>3*$H$4),"FAIL","PASS") -> PASS | N11: =IF(OR(ABS(D11-$I$3)>3*$I$4),"FAIL","PASS") -> PASS | P11: =A6 -> 0 | Q11: =IF(OR( ABS(B7-B6)>=4*$G$3, ),"FAIL","PASS") -> FAIL | R11: =IF(OR( ABS(C7-C6)>=4*$H$3, ),"FAIL","PASS") -> FAIL | S11: =IF(OR( ABS(D7-D6)>=4*$I$3, ),"FAIL","PASS") -> FAIL
A12: ='RAW DATA'!J11 -> 0 | B12: ='RAW DATA'!L11 -> 0 | C12: ='RAW DATA'!L31 -> 0 | D12: ='RAW DATA'!L51 -> 0 | F12: Minus 3σ | G12: =G3-G7 -> 0 | H12: =H3-H7 -> 0 | I12: =I3-I7 -> 0 | K12: =A12 -> 0 | L12: =IF(OR(ABS(B12-$G$3)>3*$G$4),"FAIL","PASS") -> PASS | M12: =IF(OR(ABS(C12-$H$3)>3*$H$4),"FAIL","PASS") -> PASS | N12: =IF(OR(ABS(D12-$I$3)>3*$I$4),"FAIL","PASS") -> PASS | P12: =A7 -> 0 | Q12: =IF(OR( ABS(B8-B7)>=4*$G$3, ),"FAIL","PASS") -> FAIL | R12: =IF(OR( ABS(C8-C7)>=4*$H$3, ),"FAIL","PASS") -> FAIL | S12: =IF(OR( ABS(D8-D7)>=4*$I$3, ),"FAIL","PASS") -> FAIL
A13: ='RAW DATA'!J12 -> 0 | B13: ='RAW DATA'!L12 -> 0 | C13: ='RAW DATA'!L32 -> 0 | D13: ='RAW DATA'!L52 -> 0 | K13: =A13 -> 0 | L13: =IF(OR(ABS(B13-$G$3)>3*$G$4),"FAIL","PASS") -> PASS | M13: =IF(OR(ABS(C13-$H$3)>3*$H$4),"FAIL","PASS") -> PASS | N13: =IF(OR(ABS(D13-$I$3)>3*$I$4),"FAIL","PASS") -> PASS | P13: =A8 -> 0 | Q13: =IF(OR( ABS(B9-B8)>=4*$G$3, ),"FAIL","PASS") -> FAIL | R13: =IF(OR( ABS(C9-C8)>=4*$H$3, ),"FAIL","PASS") -> FAIL | S13: =IF(OR( ABS(D9-D8)>=4*$I$3, ),"FAIL","PASS") -> FAIL
A14: ='RAW DATA'!J13 -> 0 | B14: ='RAW DATA'!L13 -> 0 | C14: ='RAW DATA'!L33 -> 0 | D14: ='RAW DATA'!L53 -> 0 | F14: Westgard Rules | K14: =A14 -> 0 | L14: =IF(OR(ABS(B14-$G$3)>3*$G$4),"FAIL","PASS") -> PASS | M14: =IF(OR(ABS(C14-$H$3)>3*$H$4),"FAIL","PASS") -> PASS | N14: =IF(OR(ABS(D14-$I$3)>3*$I$4),"FAIL","PASS") -> PASS | P14: =A9 -> 0 | Q14: =IF(OR( ABS(B10-B9)>=4*$G$3, ),"FAIL","PASS") -> FAIL | R14: =IF(OR( ABS(C10-C9)>=4*$H$3, ),"FAIL","PASS") -> FAIL | S14: =IF(OR( ABS(D10-D9)>=4*$I$3, ),"FAIL","PASS") -> FAIL
A15: ='RAW DATA'!J14 -> 0 | B15: ='RAW DATA'!L14 -> 0 | C15: ='RAW DATA'!L34 -> 0 | D15: ='RAW DATA'!L54 -> 0 | F15: 13s Rule | G15: {=IF(AND(L3:N22="PASS"), "PASS", "FAIL")} -> PASS | K15: =A15 -> 0 | L15: =IF(OR(ABS(B15-$G$3)>3*$G$4),"FAIL","PASS") -> PASS | M15: =IF(OR(ABS(C15-$H$3)>3*$H$4),"FAIL","PASS") -> PASS | N15: =IF(OR(ABS(D15-$I$3)>3*$I$4),"FAIL","PASS") -> PASS | P15: =A10 -> 0 | Q15: =IF(OR( ABS(B11-B10)>=4*$G$3, ),"FAIL","PASS") -> FAIL | R15: =IF(OR( ABS(C11-C10)>=4*$H$3, ),"FAIL","PASS") -> FAIL | S15: =IF(OR( ABS(D11-D10)>=4*$I$3, ),"FAIL","PASS") -> FAIL
A16: ='RAW DATA'!J15 -> 0 | B16: ='RAW DATA'!L15 -> 0 | C16: ='RAW DATA'!L35 -> 0 | D16: ='RAW DATA'!L55 -> 0 | F16: 22s Rule | G16: {=IF(AND(L26:N45="PASS"), "PASS", "FAIL")} -> PASS | K16: =A16 -> 0 | L16: =IF(OR(ABS(B16-$G$3)>3*$G$4),"FAIL","PASS") -> PASS | M16: =IF(OR(ABS(C16-$H$3)>3*$H$4),"FAIL","PASS") -> PASS | N16: =IF(OR(ABS(D16-$I$3)>3*$I$4),"FAIL","PASS") -> PASS | P16: =A11 -> 0 | Q16: =IF(OR( ABS(B12-B11)>=4*$G$3, ),"FAIL","PASS") -> FAIL | R16: =IF(OR( ABS(C12-C11)>=4*$H$3, ),"FAIL","PASS") -> FAIL | S16: =IF(OR( ABS(D12-D11)>=4*$I$3, ),"FAIL","PASS") -> FAIL
A17: ='RAW DATA'!J16 -> 0 | B17: ='RAW DATA'!L16 -> 0 | C17: ='RAW DATA'!L36 -> 0 | D17: ='RAW DATA'!L56 -> 0 | F17: 10x Rule | G17: {=IF(AND(Q3:S4="PASS"), "PASS", "FAIL")} -> PASS | K17: =A17 -> 0 | L17: =IF(OR(ABS(B17-$G$3)>3*$G$4),"FAIL","PASS") -> PASS | M17: =IF(OR(ABS(C17-$H$3)>3*$H$4),"FAIL","PASS") -> PASS | N17: =IF(OR(ABS(D17-$I$3)>3*$I$4),"FAIL","PASS") -> PASS | P17: =A12 -> 0 | Q17: =IF(OR( ABS(B13-B12)>=4*$G$3, ),"FAIL","PASS") -> FAIL | R17: =IF(OR( ABS(C13-C12)>=4*$H$3, ),"FAIL","PASS") -> FAIL | S17: =IF(OR( ABS(D13-D12)>=4*$I$3, ),"FAIL","PASS") -> FAIL
A18: ='RAW DATA'!J17 -> 0 | B18: ='RAW DATA'!L17 -> 0 | C18: ='RAW DATA'!L37 -> 0 | D18: ='RAW DATA'!L57 -> 0 | F18: R4s Rule | G18: {=IF(AND(Q8:S27="PASS"), "PASS", "FAIL")} -> FAIL | K18: =A18 -> 0 | L18: =IF(OR(ABS(B18-$G$3)>3*$G$4),"FAIL","PASS") -> PASS | M18: =IF(OR(ABS(C18-$H$3)>3*$H$4),"FAIL","PASS") -> PASS | N18: =IF(OR(ABS(D18-$I$3)>3*$I$4),"FAIL","PASS") -> PASS | P18: =A13 -> 0 | Q18: =IF(OR( ABS(B14-B13)>=4*$G$3, ),"FAIL","PASS") -> FAIL | R18: =IF(OR( ABS(C14-C13)>=4*$H$3, ),"FAIL","PASS") -> FAIL | S18: =IF(OR( ABS(D14-D13)>=4*$I$3, ),"FAIL","PASS") -> FAIL
A19: ='RAW DATA'!J18 -> 0 | B19: ='RAW DATA'!L18 -> 0 | C19: ='RAW DATA'!L38 -> 0 | D19: ='RAW DATA'!L58 -> 0 | K19: =A19 -> 0 | L19: =IF(OR(ABS(B19-$G$3)>3*$G$4),"FAIL","PASS") -> PASS | M19: =IF(OR(ABS(C19-$H$3)>3*$H$4),"FAIL","PASS") -> PASS | N19: =IF(OR(ABS(D19-$I$3)>3*$I$4),"FAIL","PASS") -> PASS | P19: =A14 -> 0 | Q19: =IF(OR( ABS(B15-B14)>=4*$G$3, ),"FAIL","PASS") -> FAIL | R19: =IF(OR( ABS(C15-C14)>=4*$H$3, ),"FAIL","PASS") -> FAIL | S19: =IF(OR( ABS(D15-D14)>=4*$I$3, ),"FAIL","PASS") -> FAIL
A20: ='RAW DATA'!J19 -> 0 | B20: ='RAW DATA'!L19 -> 0 | C20: ='RAW DATA'!L39 -> 0 | D20: ='RAW DATA'!L59 -> 0 | K20: =A20 -> 0 | L20: =IF(OR(ABS(B20-$G$3)>3*$G$4),"FAIL","PASS") -> PASS | M20: =IF(OR(ABS(C20-$H$3)>3*$H$4),"FAIL","PASS") -> PASS | N20: =IF(OR(ABS(D20-$I$3)>3*$I$4),"FAIL","PASS") -> PASS | P20: =A15 -> 0 | Q20: =IF(OR( ABS(B16-B15)>=4*$G$3, ),"FAIL","PASS") -> FAIL | R20: =IF(OR( ABS(C16-C15)>=4*$H$3, ),"FAIL","PASS") -> FAIL | S20: =IF(OR( ABS(D16-D15)>=4*$I$3, ),"FAIL","PASS") -> FAIL
A21: ='RAW DATA'!J20 -> 0 | B21: ='RAW DATA'!L20 -> 0 | C21: ='RAW DATA'!L40 -> 0 | D21: ='RAW DATA'!L60 -> 0 | K21: =A21 -> 0 | L21: =IF(OR(ABS(B21-$G$3)>3*$G$4),"FAIL","PASS") -> PASS | M21: =IF(OR(ABS(C21-$H$3)>3*$H$4),"FAIL","PASS") -> PASS | N21: =IF(OR(ABS(D21-$I$3)>3*$I$4),"FAIL","PASS") -> PASS | P21: =A16 -> 0 | Q21: =IF(OR( ABS(B17-B16)>=4*$G$3, ),"FAIL","PASS") -> FAIL | R21: =IF(OR( ABS(C17-C16)>=4*$H$3, ),"FAIL","PASS") -> FAIL | S21: =IF(OR( ABS(D17-D16)>=4*$I$3, ),"FAIL","PASS") -> FAIL
A22: ='RAW DATA'!J21 -> 0 | B22: ='RAW DATA'!L21 -> 0 | C22: ='RAW DATA'!L41 -> 0 | D22: ='RAW DATA'!L61 -> 0 | K22: =A22 -> 0 | L22: =IF(OR(ABS(B22-$G$3)>3*$G$4),"FAIL","PASS") -> PASS | M22: =IF(OR(ABS(C22-$H$3)>3*$H$4),"FAIL","PASS") -> PASS | N22: =IF(OR(ABS(D22-$I$3)>3*$I$4),"FAIL","PASS") -> PASS | P22: =A17 -> 0 | Q22: =IF(OR( ABS(B18-B17)>=4*$G$3, ),"FAIL","PASS") -> FAIL | R22: =IF(OR( ABS(C18-C17)>=4*$H$3, ),"FAIL","PASS") -> FAIL | S22: =IF(OR( ABS(D18-D17)>=4*$I$3, ),"FAIL","PASS") -> FAIL
P23: =A18 -> 0 | Q23: =IF(OR( ABS(B19-B18)>=4*$G$3, ),"FAIL","PASS") -> FAIL | R23: =IF(OR( ABS(C19-C18)>=4*$H$3, ),"FAIL","PASS") -> FAIL | S23: =IF(OR( ABS(D19-D18)>=4*$I$3, ),"FAIL","PASS") -> FAIL
K24: 22s Rule | P24: =A19 -> 0 | Q24: =IF(OR( ABS(B20-B19)>=4*$G$3, ),"FAIL","PASS") -> FAIL | R24: =IF(OR( ABS(C20-C19)>=4*$H$3, ),"FAIL","PASS") -> FAIL | S24: =IF(OR( ABS(D20-D19)>=4*$I$3, ),"FAIL","PASS") -> FAIL
L25: QCL | M25: QCM | N25: QCH | P25: =A20 -> 0 | Q25: =IF(OR( ABS(B21-B20)>=4*$G$3, ),"FAIL","PASS") -> FAIL | R25: =IF(OR( ABS(C21-C20)>=4*$H$3, ),"FAIL","PASS") -> FAIL | S25: =IF(OR( ABS(D21-D20)>=4*$I$3, ),"FAIL","PASS") -> FAIL
K26: =A3 -> 0 | L26: =IF(OR( AND(B3-$G$3>2*$G$4,B4-$G$3>2*$G$4), AND(B3-$G$3<-2*$G$4,B4-$G$3<-2*$G$4)),"FAIL","PASS") -> PASS | M26: =IF(OR( AND(C3-$H$3>2*$H$4,C4-$H$3>2*$H$4), AND(C3-$H$3<-2*$H$4,C4-$H$3<-2*$H$4)),"FAIL","PASS") -> PASS | N26: =IF(OR( AND(D3-$I$3>2*$I$4,D4-$I$3>2*$I$4), AND(D3-$I$3<-2*$I$4,D4-$I$3<-2*$I$4)),"FAIL","PASS") -> PASS | P26: =A21 -> 0 | Q26: =IF(OR( ABS(B22-B21)>=4*$G$3, ),"FAIL","PASS") -> FAIL | R26: =IF(OR( ABS(C22-C21)>=4*$H$3, ),"FAIL","PASS") -> FAIL | S26: =IF(OR( ABS(D22-D21)>=4*$I$3, ),"FAIL","PASS") -> FAIL
K27: =A4 -> 0 | L27: =IF(OR( AND(B4-$G$3>2*$G$4,B5-$G$3>2*$G$4), AND(B4-$G$3<-2*$G$4,B5-$G$3<-2*$G$4)),"FAIL","PASS") -> PASS | M27: =IF(OR( AND(C4-$H$3>2*$H$4,C5-$H$3>2*$H$4), AND(C4-$H$3<-2*$H$4,C5-$H$3<-2*$H$4)),"FAIL","PASS") -> PASS | N27: =IF(OR( AND(D4-$I$3>2*$I$4,D5-$I$3>2*$I$4), AND(D4-$I$3<-2*$I$4,D5-$I$3<-2*$I$4)),"FAIL","PASS") -> PASS | P27: =A22 -> 0 | Q27: =IF(OR( ABS(B23-B22)>=4*$G$3, ),"FAIL","PASS") -> FAIL | R27: =IF(OR( ABS(C23-C22)>=4*$H$3, ),"FAIL","PASS") -> FAIL | S27: =IF(OR( ABS(D23-D22)>=4*$I$3, ),"FAIL","PASS") -> FAIL
K28: =A5 -> 0 | L28: =IF(OR( AND(B5-$G$3>2*$G$4,B6-$G$3>2*$G$4), AND(B5-$G$3<-2*$G$4,B6-$G$3<-2*$G$4)),"FAIL","PASS") -> PASS | M28: =IF(OR( AND(C5-$H$3>2*$H$4,C6-$H$3>2*$H$4), AND(C5-$H$3<-2*$H$4,C6-$H$3<-2*$H$4)),"FAIL","PASS") -> PASS | N28: =IF(OR( AND(D5-$I$3>2*$I$4,D6-$I$3>2*$I$4), AND(D5-$I$3<-2*$I$4,D6-$I$3<-2*$I$4)),"FAIL","PASS") -> PASS
K29: =A6 -> 0 | L29: =IF(OR( AND(B6-$G$3>2*$G$4,B7-$G$3>2*$G$4), AND(B6-$G$3<-2*$G$4,B7-$G$3<-2*$G$4)),"FAIL","PASS") -> PASS | M29: =IF(OR( AND(C6-$H$3>2*$H$4,C7-$H$3>2*$H$4), AND(C6-$H$3<-2*$H$4,C7-$H$3<-2*$H$4)),"FAIL","PASS") -> PASS | N29: =IF(OR( AND(D6-$I$3>2*$I$4,D7-$I$3>2*$I$4), AND(D6-$I$3<-2*$I$4,D7-$I$3<-2*$I$4)),"FAIL","PASS") -> PASS
K30: =A7 -> 0 | L30: =IF(OR( AND(B7-$G$3>2*$G$4,B8-$G$3>2*$G$4), AND(B7-$G$3<-2*$G$4,B8-$G$3<-2*$G$4)),"FAIL","PASS") -> PASS | M30: =IF(OR( AND(C7-$H$3>2*$H$4,C8-$H$3>2*$H$4), AND(C7-$H$3<-2*$H$4,C8-$H$3<-2*$H$4)),"FAIL","PASS") -> PASS | N30: =IF(OR( AND(D7-$I$3>2*$I$4,D8-$I$3>2*$I$4), AND(D7-$I$3<-2*$I$4,D8-$I$3<-2*$I$4)),"FAIL","PASS") -> PASS
K31: =A8 -> 0 | L31: =IF(OR( AND(B8-$G$3>2*$G$4,B9-$G$3>2*$G$4), AND(B8-$G$3<-2*$G$4,B9-$G$3<-2*$G$4)),"FAIL","PASS") -> PASS | M31: =IF(OR( AND(C8-$H$3>2*$H$4,C9-$H$3>2*$H$4), AND(C8-$H$3<-2*$H$4,C9-$H$3<-2*$H$4)),"FAIL","PASS") -> PASS | N31: =IF(OR( AND(D8-$I$3>2*$I$4,D9-$I$3>2*$I$4), AND(D8-$I$3<-2*$I$4,D9-$I$3<-2*$I$4)),"FAIL","PASS") -> PASS
K32: =A9 -> 0 | L32: =IF(OR( AND(B9-$G$3>2*$G$4,B10-$G$3>2*$G$4), AND(B9-$G$3<-2*$G$4,B10-$G$3<-2*$G$4)),"FAIL","PASS") -> PASS | M32: =IF(OR( AND(C9-$H$3>2*$H$4,C10-$H$3>2*$H$4), AND(C9-$H$3<-2*$H$4,C10-$H$3<-2*$H$4)),"FAIL","PASS") -> PASS | N32: =IF(OR( AND(D9-$I$3>2*$I$4,D10-$I$3>2*$I$4), AND(D9-$I$3<-2*$I$4,D10-$I$3<-2*$I$4)),"FAIL","PASS") -> PASS
K33: =A10 -> 0 | L33: =IF(OR( AND(B10-$G$3>2*$G$4,B11-$G$3>2*$G$4), AND(B10-$G$3<-2*$G$4,B11-$G$3<-2*$G$4)),"FAIL","PASS") -> PASS | M33: =IF(OR( AND(C10-$H$3>2*$H$4,C11-$H$3>2*$H$4), AND(C10-$H$3<-2*$H$4,C11-$H$3<-2*$H$4)),"FAIL","PASS") -> PASS | N33: =IF(OR( AND(D10-$I$3>2*$I$4,D11-$I$3>2*$I$4), AND(D10-$I$3<-2*$I$4,D11-$I$3<-2*$I$4)),"FAIL","PASS") -> PASS
K34: =A11 -> 0 | L34: =IF(OR( AND(B11-$G$3>2*$G$4,B12-$G$3>2*$G$4), AND(B11-$G$3<-2*$G$4,B12-$G$3<-2*$G$4)),"FAIL","PASS") -> PASS | M34: =IF(OR( AND(C11-$H$3>2*$H$4,C12-$H$3>2*$H$4), AND(C11-$H$3<-2*$H$4,C12-$H$3<-2*$H$4)),"FAIL","PASS") -> PASS | N34: =IF(OR( AND(D11-$I$3>2*$I$4,D12-$I$3>2*$I$4), AND(D11-$I$3<-2*$I$4,D12-$I$3<-2*$I$4)),"FAIL","PASS") -> PASS
K35: =A12 -> 0 | L35: =IF(OR( AND(B12-$G$3>2*$G$4,B13-$G$3>2*$G$4), AND(B12-$G$3<-2*$G$4,B13-$G$3<-2*$G$4)),"FAIL","PASS") -> PASS | M35: =IF(OR( AND(C12-$H$3>2*$H$4,C13-$H$3>2*$H$4), AND(C12-$H$3<-2*$H$4,C13-$H$3<-2*$H$4)),"FAIL","PASS") -> PASS | N35: =IF(OR( AND(D12-$I$3>2*$I$4,D13-$I$3>2*$I$4), AND(D12-$I$3<-2*$I$4,D13-$I$3<-2*$I$4)),"FAIL","PASS") -> PASS
K36: =A13 -> 0 | L36: =IF(OR( AND(B13-$G$3>2*$G$4,B14-$G$3>2*$G$4), AND(B13-$G$3<-2*$G$4,B14-$G$3<-2*$G$4)),"FAIL","PASS") -> PASS | M36: =IF(OR( AND(C13-$H$3>2*$H$4,C14-$H$3>2*$H$4), AND(C13-$H$3<-2*$H$4,C14-$H$3<-2*$H$4)),"FAIL","PASS") -> PASS | N36: =IF(OR( AND(D13-$I$3>2*$I$4,D14-$I$3>2*$I$4), AND(D13-$I$3<-2*$I$4,D14-$I$3<-2*$I$4)),"FAIL","PASS") -> PASS
K37: =A14 -> 0 | L37: =IF(OR( AND(B14-$G$3>2*$G$4,B15-$G$3>2*$G$4), AND(B14-$G$3<-2*$G$4,B15-$G$3<-2*$G$4)),"FAIL","PASS") -> PASS | M37: =IF(OR( AND(C14-$H$3>2*$H$4,C15-$H$3>2*$H$4), AND(C14-$H$3<-2*$H$4,C15-$H$3<-2*$H$4)),"FAIL","PASS") -> PASS | N37: =IF(OR( AND(D14-$I$3>2*$I$4,D15-$I$3>2*$I$4), AND(D14-$I$3<-2*$I$4,D15-$I$3<-2*$I$4)),"FAIL","PASS") -> PASS
K38: =A15 -> 0 | L38: =IF(OR( AND(B15-$G$3>2*$G$4,B16-$G$3>2*$G$4), AND(B15-$G$3<-2*$G$4,B16-$G$3<-2*$G$4)),"FAIL","PASS") -> PASS | M38: =IF(OR( AND(C15-$H$3>2*$H$4,C16-$H$3>2*$H$4), AND(C15-$H$3<-2*$H$4,C16-$H$3<-2*$H$4)),"FAIL","PASS") -> PASS | N38: =IF(OR( AND(D15-$I$3>2*$I$4,D16-$I$3>2*$I$4), AND(D15-$I$3<-2*$I$4,D16-$I$3<-2*$I$4)),"FAIL","PASS") -> PASS
K39: =A16 -> 0 | L39: =IF(OR( AND(B16-$G$3>2*$G$4,B17-$G$3>2*$G$4), AND(B16-$G$3<-2*$G$4,B17-$G$3<-2*$G$4)),"FAIL","PASS") -> PASS | M39: =IF(OR( AND(C16-$H$3>2*$H$4,C17-$H$3>2*$H$4), AND(C16-$H$3<-2*$H$4,C17-$H$3<-2*$H$4)),"FAIL","PASS") -> PASS | N39: =IF(OR( AND(D16-$I$3>2*$I$4,D17-$I$3>2*$I$4), AND(D16-$I$3<-2*$I$4,D17-$I$3<-2*$I$4)),"FAIL","PASS") -> PASS
... K45: =A22 -> 0 | L45: =IF(OR( AND(B22-$G$3>2*$G$4,B23-$G$3>2*$G$4), AND(B22-$G$3<-2*$G$4,B23-$G$3<-2*$G$4)),"FAIL","PASS") -> PASS | M45: =IF(OR( AND(C22-$H$3>2*$H$4,C23-$H$3>2*$H$4), AND(C22-$H$3<-2*$H$4,C23-$H$3<-2*$H$4)),"FAIL","PASS") -> PASS | N45: =IF(OR( AND(D22-$I$3>2*$I$4,D23-$I$3>2*$I$4), AND(D22-$I$3<-2*$I$4,D23-$I$3<-2*$I$4)),"FAIL","PASS") -> PASS

Sheet Charts
A1: QCL
A3: Date | B3: Result | C3: Mean | D3: Plus 2σ | E3: Plus 3σ | F3: Minus 2σ | G3: Minus 3σ
A4: ='Westgard Rules'!A3 -> 0 | B4: ='Westgard Rules'!B3 -> 0 | C4: ='Westgard Rules'!$G$3 -> 0 | D4: ='Westgard Rules'!$G$9 -> 0 | E4: ='Westgard Rules'!$G$10 -> 0 | F4: ='Westgard Rules'!$G$11 -> 0 | G4: ='Westgard Rules'!$G$12 -> 0
A5: ='Westgard Rules'!A4 -> 0 | B5: ='Westgard Rules'!B4 -> 0 | C5: ='Westgard Rules'!$G$3 -> 0 | D5: ='Westgard Rules'!$G$9 -> 0 | E5: ='Westgard Rules'!$G$10 -> 0 | F5: ='Westgard Rules'!$G$11 -> 0 | G5: ='Westgard Rules'!$G$12 -> 0
A6: ='Westgard Rules'!A5 -> 0 | B6: ='Westgard Rules'!B5 -> 0 | C6: ='Westgard Rules'!$G$3 -> 0 | D6: ='Westgard Rules'!$G$9 -> 0 | E6: ='Westgard Rules'!$G$10 -> 0 | F6: ='Westgard Rules'!$G$11 -> 0 | G6: ='Westgard Rules'!$G$12 -> 0
A7: ='Westgard Rules'!A6 -> 0 | B7: ='Westgard Rules'!B6 -> 0 | C7: ='Westgard Rules'!$G$3 -> 0 | D7: ='Westgard Rules'!$G$9 -> 0 | E7: ='Westgard Rules'!$G$10 -> 0 | F7: ='Westgard Rules'!$G$11 -> 0 | G7: ='Westgard Rules'!$G$12 -> 0
A8: ='Westgard Rules'!A7 -> 0 | B8: ='Westgard Rules'!B7 -> 0 | C8: ='Westgard Rules'!$G$3 -> 0 | D8: ='Westgard Rules'!$G$9 -> 0 | E8: ='Westgard Rules'!$G$10 -> 0 | F8: ='Westgard Rules'!$G$11 -> 0 | G8: ='Westgard Rules'!$G$12 -> 0
A9: ='Westgard Rules'!A8 -> 0 | B9: ='Westgard Rules'!B8 -> 0 | C9: ='Westgard Rules'!$G$3 -> 0 | D9: ='Westgard Rules'!$G$9 -> 0 | E9: ='Westgard Rules'!$G$10 -> 0 | F9: ='Westgard Rules'!$G$11 -> 0 | G9: ='Westgard Rules'!$G$12 -> 0
A10: ='Westgard Rules'!A9 -> 0 | B10: ='Westgard Rules'!B9 -> 0 | C10: ='Westgard Rules'!$G$3 -> 0 | D10: ='Westgard Rules'!$G$9 -> 0 | E10: ='Westgard Rules'!$G$10 -> 0 | F10: ='Westgard Rules'!$G$11 -> 0 | G10: ='Westgard Rules'!$G$12 -> 0
A11: ='Westgard Rules'!A10 -> 0 | B11: ='Westgard Rules'!B10 -> 0 | C11: ='Westgard Rules'!$G$3 -> 0 | D11: ='Westgard Rules'!$G$9 -> 0 | E11: ='Westgard Rules'!$G$10 -> 0 | F11: ='Westgard Rules'!$G$11 -> 0 | G11: ='Westgard Rules'!$G$12 -> 0
A12: ='Westgard Rules'!A11 -> 0 | B12: ='Westgard Rules'!B11 -> 0 | C12: ='Westgard Rules'!$G$3 -> 0 | D12: ='Westgard Rules'!$G$9 -> 0 | E12: ='Westgard Rules'!$G$10 -> 0 | F12: ='Westgard Rules'!$G$11 -> 0 | G12: ='Westgard Rules'!$G$12 -> 0
A13: ='Westgard Rules'!A12 -> 0 | B13: ='Westgard Rules'!B12 -> 0 | C13: ='Westgard Rules'!$G$3 -> 0 | D13: ='Westgard Rules'!$G$9 -> 0 | E13: ='Westgard Rules'!$G$10 -> 0 | F13: ='Westgard Rules'!$G$11 -> 0 | G13: ='Westgard Rules'!$G$12 -> 0
A14: ='Westgard Rules'!A13 -> 0 | B14: ='Westgard Rules'!B13 -> 0 | C14: ='Westgard Rules'!$G$3 -> 0 | D14: ='Westgard Rules'!$G$9 -> 0 | E14: ='Westgard Rules'!$G$10 -> 0 | F14: ='Westgard Rules'!$G$11 -> 0 | G14: ='Westgard Rules'!$G$12 -> 0
A15: ='Westgard Rules'!A14 -> 0 | B15: ='Westgard Rules'!B14 -> 0 | C15: ='Westgard Rules'!$G$3 -> 0 | D15: ='Westgard Rules'!$G$9 -> 0 | E15: ='Westgard Rules'!$G$10 -> 0 | F15: ='Westgard Rules'!$G$11 -> 0 | G15: ='Westgard Rules'!$G$12 -> 0
... A23: ='Westgard Rules'!A22 -> 0 | B23: ='Westgard Rules'!B22 -> 0 | C23: ='Westgard Rules'!$G$3 -> 0 | D23: ='Westgard Rules'!$G$9 -> 0 | E23: ='Westgard Rules'!$G$10 -> 0 | F23: ='Westgard Rules'!$G$11 -> 0 | G23: ='Westgard Rules'!$G$12 -> 0
A26: QCM
A28: Date | B28: Result | C28: Mean | D28: Plus 2σ | E28: Plus 3σ | F28: Minus 2σ | G28: Minus 3σ
A29: =A4 -> 0 | B29: ='Westgard Rules'!C3 -> 0 | C29: ='Westgard Rules'!$H$3 -> 0 | D29: ='Westgard Rules'!$H$9 -> 0 | E29: ='Westgard Rules'!$H$10 -> 0 | F29: ='Westgard Rules'!$H$11 -> 0 | G29: ='Westgard Rules'!$H$12 -> 0
A30: =A5 -> 0 | B30: ='Westgard Rules'!C4 -> 0 | C30: ='Westgard Rules'!$H$3 -> 0 | D30: ='Westgard Rules'!$H$9 -> 0 | E30: ='Westgard Rules'!$H$10 -> 0 | F30: ='Westgard Rules'!$H$11 -> 0 | G30: ='Westgard Rules'!$H$12 -> 0
A31: =A6 -> 0 | B31: ='Westgard Rules'!C5 -> 0 | C31: ='Westgard Rules'!$H$3 -> 0 | D31: ='Westgard Rules'!$H$9 -> 0 | E31: ='Westgard Rules'!$H$10 -> 0 | F31: ='Westgard Rules'!$H$11 -> 0 | G31: ='Westgard Rules'!$H$12 -> 0
A32: =A7 -> 0 | B32: ='Westgard Rules'!C6 -> 0 | C32: ='Westgard Rules'!$H$3 -> 0 | D32: ='Westgard Rules'!$H$9 -> 0 | E32: ='Westgard Rules'!$H$10 -> 0 | F32: ='Westgard Rules'!$H$11 -> 0 | G32: ='Westgard Rules'!$H$12 -> 0
A33: =A8 -> 0 | B33: ='Westgard Rules'!C7 -> 0 | C33: ='Westgard Rules'!$H$3 -> 0 | D33: ='Westgard Rules'!$H$9 -> 0 | E33: ='Westgard Rules'!$H$10 -> 0 | F33: ='Westgard Rules'!$H$11 -> 0 | G33: ='Westgard Rules'!$H$12 -> 0
A34: =A9 -> 0 | B34: ='Westgard Rules'!C8 -> 0 | C34: ='Westgard Rules'!$H$3 -> 0 | D34: ='Westgard Rules'!$H$9 -> 0 | E34: ='Westgard Rules'!$H$10 -> 0 | F34: ='Westgard Rules'!$H$11 -> 0 | G34: ='Westgard Rules'!$H$12 -> 0
A35: =A10 -> 0 | B35: ='Westgard Rules'!C9 -> 0 | C35: ='Westgard Rules'!$H$3 -> 0 | D35: ='Westgard Rules'!$H$9 -> 0 | E35: ='Westgard Rules'!$H$10 -> 0 | F35: ='Westgard Rules'!$H$11 -> 0 | G35: ='Westgard Rules'!$H$12 -> 0
A36: =A11 -> 0 | B36: ='Westgard Rules'!C10 -> 0 | C36: ='Westgard Rules'!$H$3 -> 0 | D36: ='Westgard Rules'!$H$9 -> 0 | E36: ='Westgard Rules'!$H$10 -> 0 | F36: ='Westgard Rules'!$H$11 -> 0 | G36: ='Westgard Rules'!$H$12 -> 0
A37: =A12 -> 0 | B37: ='Westgard Rules'!C11 -> 0 | C37: ='Westgard Rules'!$H$3 -> 0 | D37: ='Westgard Rules'!$H$9 -> 0 | E37: ='Westgard Rules'!$H$10 -> 0 | F37: ='Westgard Rules'!$H$11 -> 0 | G37: ='Westgard Rules'!$H$12 -> 0
A38: =A13 -> 0 | B38: ='Westgard Rules'!C12 -> 0 | C38: ='Westgard Rules'!$H$3 -> 0 | D38: ='Westgard Rules'!$H$9 -> 0 | E38: ='Westgard Rules'!$H$10 -> 0 | F38: ='Westgard Rules'!$H$11 -> 0 | G38: ='Westgard Rules'!$H$12 -> 0
A39: =A14 -> 0 | B39: ='Westgard Rules'!C13 -> 0 | C39: ='Westgard Rules'!$H$3 -> 0 | D39: ='Westgard Rules'!$H$9 -> 0 | E39: ='Westgard Rules'!$H$10 -> 0 | F39: ='Westgard Rules'!$H$11 -> 0 | G39: ='Westgard Rules'!$H$12 -> 0
A40: =A15 -> 0 | B40: ='Westgard Rules'!C14 -> 0 | C40: ='Westgard Rules'!$H$3 -> 0 | D40: ='Westgard Rules'!$H$9 -> 0 | E40: ='Westgard Rules'!$H$10 -> 0 | F40: ='Westgard Rules'!$H$11 -> 0 | G40: ='Westgard Rules'!$H$12 -> 0
... A48: =A23 -> 0 | B48: ='Westgard Rules'!C22 -> 0 | C48: ='Westgard Rules'!$H$3 -> 0 | D48: ='Westgard Rules'!$H$9 -> 0 | E48: ='Westgard Rules'!$H$10 -> 0 | F48: ='Westgard Rules'!$H$11 -> 0 | G48: ='Westgard Rules'!$H$12 -> 0
A51: QCH
A53: Date | B53: Result | C53: Mean | D53: Plus 2σ | E53: Plus 3σ | F53: Minus 2σ | G53: Minus 3σ
A54: =A29 -> 0 | B54: ='Westgard Rules'!D3 -> 0 | C54: ='Westgard Rules'!$I$3 -> 0 | D54: ='Westgard Rules'!$I$9 -> 0 | E54: ='Westgard Rules'!$I$10 -> 0 | F54: ='Westgard Rules'!$I$11 -> 0 | G54: ='Westgard Rules'!$I$12 -> 0
A55: =A30 -> 0 | B55: ='Westgard Rules'!D4 -> 0 | C55: ='Westgard Rules'!$I$3 -> 0 | D55: ='Westgard Rules'!$I$9 -> 0 | E55: ='Westgard Rules'!$I$10 -> 0 | F55: ='Westgard Rules'!$I$11 -> 0 | G55: ='Westgard Rules'!$I$12 -> 0
A56: =A31 -> 0 | B56: ='Westgard Rules'!D5 -> 0 | C56: ='Westgard Rules'!$I$3 -> 0 | D56: ='Westgard Rules'!$I$9 -> 0 | E56: ='Westgard Rules'!$I$10 -> 0 | F56: ='Westgard Rules'!$I$11 -> 0 | G56: ='Westgard Rules'!$I$12 -> 0
A57: =A32 -> 0 | B57: ='Westgard Rules'!D6 -> 0 | C57: ='Westgard Rules'!$I$3 -> 0 | D57: ='Westgard Rules'!$I$9 -> 0 | E57: ='Westgard Rules'!$I$10 -> 0 | F57: ='Westgard Rules'!$I$11 -> 0 | G57: ='Westgard Rules'!$I$12 -> 0
A58: =A33 -> 0 | B58: ='Westgard Rules'!D7 -> 0 | C58: ='Westgard Rules'!$I$3 -> 0 | D58: ='Westgard Rules'!$I$9 -> 0 | E58: ='Westgard Rules'!$I$10 -> 0 | F58: ='Westgard Rules'!$I$11 -> 0 | G58: ='Westgard Rules'!$I$12 -> 0
A59: =A34 -> 0 | B59: ='Westgard Rules'!D8 -> 0 | C59: ='Westgard Rules'!$I$3 -> 0 | D59: ='Westgard Rules'!$I$9 -> 0 | E59: ='Westgard Rules'!$I$10 -> 0 | F59: ='Westgard Rules'!$I$11 -> 0 | G59: ='Westgard Rules'!$I$12 -> 0
A60: =A35 -> 0 | B60: ='Westgard Rules'!D9 -> 0 | C60: ='Westgard Rules'!$I$3 -> 0 | D60: ='Westgard Rules'!$I$9 -> 0 | E60: ='Westgard Rules'!$I$10 -> 0 | F60: ='Westgard Rules'!$I$11 -> 0 | G60: ='Westgard Rules'!$I$12 -> 0
A61: =A36 -> 0 | B61: ='Westgard Rules'!D10 -> 0 | C61: ='Westgard Rules'!$I$3 -> 0 | D61: ='Westgard Rules'!$I$9 -> 0 | E61: ='Westgard Rules'!$I$10 -> 0 | F61: ='Westgard Rules'!$I$11 -> 0 | G61: ='Westgard Rules'!$I$12 -> 0
...

Sheet RAW DATA
A1: Activity_Type | B1: Specimen_ID | C1: Patient_ID | D1: Sample_Type | E1: Received_dt | F1: Collection_dt | G1: Sample_ID | H1: Agent_Category | I1: Analyte_LOINC | J1: Test_dt | K1: Result_CODED | L1: Result_NUMERIC | M1: Unit_Of_Measure | N1: Instrument_Type | O1: Patient_State | P1: Patient_County | Q1: Patient_Zip | R1: Patient_DOB | S1: Patient_Age | T1: Age_Unit | U1: Patient_Sex | V1: Patient_Race | W1: Patient_Ethnicity | X1: Analyst | Y1: Instrument_ID | Z1: Run_ID | AA1: R2_Value | AB1: QC_Material_Lot | AC1: Comments | AD1: SortOrder
AD62: =MATCH(G:G,{"QL","QM","QH"},0) -> #N/A
AD63: =MATCH(G:G,{"QL","QM","QH"},0) -> #N/A
AD64: =MATCH(G:G,{"QL","QM","QH"},0) -> #N/A
